ERROR 2025-08-23 23:16:22,526 log 13140 8220 Internal Server Error: /api/auth/login/
Traceback (most recent call last):
  File "C:\Users\A\Desktop\Digitall Skills\RH_App\venv\Lib\site-packages\django\db\backends\utils.py", line 105, in _execute
    return self.cursor.execute(sql, params)
           ~~~~~~~~~~~~~~~~~~~^^^^^^^^^^^^^
  File "C:\Users\A\Desktop\Digitall Skills\RH_App\venv\Lib\site-packages\django\db\backends\sqlite3\base.py", line 328, in execute
    return super().execute(query, params)
           ~~~~~~~~~~~~~~~^^^^^^^^^^^^^^^
sqlite3.OperationalError: no such table: users

The above exception was the direct cause of the following exception:

Traceback (most recent call last):
  File "C:\Users\A\Desktop\Digitall Skills\RH_App\venv\Lib\site-packages\django\core\handlers\exception.py", line 55, in inner
    response = get_response(request)
  File "C:\Users\A\Desktop\Digitall Skills\RH_App\venv\Lib\site-packages\django\core\handlers\base.py", line 197, in _get_response
    response = wrapped_callback(request, *callback_args, **callback_kwargs)
  File "C:\Users\A\Desktop\Digitall Skills\RH_App\venv\Lib\site-packages\django\views\decorators\csrf.py", line 65, in _view_wrapper
    return view_func(request, *args, **kwargs)
  File "C:\Users\A\Desktop\Digitall Skills\RH_App\venv\Lib\site-packages\django\views\generic\base.py", line 104, in view
    return self.dispatch(request, *args, **kwargs)
           ~~~~~~~~~~~~~^^^^^^^^^^^^^^^^^^^^^^^^^^
  File "C:\Users\A\Desktop\Digitall Skills\RH_App\venv\Lib\site-packages\rest_framework\views.py", line 509, in dispatch
    response = self.handle_exception(exc)
  File "C:\Users\A\Desktop\Digitall Skills\RH_App\venv\Lib\site-packages\rest_framework\views.py", line 469, in handle_exception
    self.raise_uncaught_exception(exc)
    ~~~~~~~~~~~~~~~~~~~~~~~~~~~~~^^^^^
  File "C:\Users\A\Desktop\Digitall Skills\RH_App\venv\Lib\site-packages\rest_framework\views.py", line 480, in raise_uncaught_exception
    raise exc
  File "C:\Users\A\Desktop\Digitall Skills\RH_App\venv\Lib\site-packages\rest_framework\views.py", line 506, in dispatch
    response = handler(request, *args, **kwargs)
  File "C:\Users\A\Desktop\Digitall Skills\RH_App\venv\Lib\site-packages\rest_framework_simplejwt\views.py", line 46, in post
    serializer.is_valid(raise_exception=True)
    ~~~~~~~~~~~~~~~~~~~^^^^^^^^^^^^^^^^^^^^^^
  File "C:\Users\A\Desktop\Digitall Skills\RH_App\venv\Lib\site-packages\rest_framework\serializers.py", line 227, in is_valid
    self._validated_data = self.run_validation(self.initial_data)
                           ~~~~~~~~~~~~~~~~~~~^^^^^^^^^^^^^^^^^^^
  File "C:\Users\A\Desktop\Digitall Skills\RH_App\venv\Lib\site-packages\rest_framework\serializers.py", line 429, in run_validation
    value = self.validate(value)
  File "C:\Users\A\Desktop\Digitall Skills\RH_App\venv\Lib\site-packages\rest_framework_simplejwt\serializers.py", line 73, in validate
    data = super().validate(attrs)
  File "C:\Users\A\Desktop\Digitall Skills\RH_App\venv\Lib\site-packages\rest_framework_simplejwt\serializers.py", line 54, in validate
    self.user = authenticate(**authenticate_kwargs)
                ~~~~~~~~~~~~^^^^^^^^^^^^^^^^^^^^^^^
  File "C:\Users\A\Desktop\Digitall Skills\RH_App\venv\Lib\site-packages\django\views\decorators\debug.py", line 73, in sensitive_variables_wrapper
    return func(*func_args, **func_kwargs)
  File "C:\Users\A\Desktop\Digitall Skills\RH_App\venv\Lib\site-packages\django\contrib\auth\__init__.py", line 79, in authenticate
    user = backend.authenticate(request, **credentials)
  File "C:\Users\A\Desktop\Digitall Skills\RH_App\venv\Lib\site-packages\django\contrib\auth\backends.py", line 42, in authenticate
    user = UserModel._default_manager.get_by_natural_key(username)
  File "C:\Users\A\Desktop\Digitall Skills\RH_App\venv\Lib\site-packages\django\contrib\auth\base_user.py", line 55, in get_by_natural_key
    return self.get(**{self.model.USERNAME_FIELD: username})
           ~~~~~~~~^^^^^^^^^^^^^^^^^^^^^^^^^^^^^^^^^^^^^^^^^
  File "C:\Users\A\Desktop\Digitall Skills\RH_App\venv\Lib\site-packages\django\db\models\manager.py", line 87, in manager_method
    return getattr(self.get_queryset(), name)(*args, **kwargs)
           ~~~~~~~~~~~~~~~~~~~~~~~~~~~~~~~~~~^^^^^^^^^^^^^^^^^
  File "C:\Users\A\Desktop\Digitall Skills\RH_App\venv\Lib\site-packages\django\db\models\query.py", line 643, in get
    num = len(clone)
  File "C:\Users\A\Desktop\Digitall Skills\RH_App\venv\Lib\site-packages\django\db\models\query.py", line 380, in __len__
    self._fetch_all()
    ~~~~~~~~~~~~~~~^^
  File "C:\Users\A\Desktop\Digitall Skills\RH_App\venv\Lib\site-packages\django\db\models\query.py", line 1926, in _fetch_all
    self._result_cache = list(self._iterable_class(self))
                         ~~~~^^^^^^^^^^^^^^^^^^^^^^^^^^^^
  File "C:\Users\A\Desktop\Digitall Skills\RH_App\venv\Lib\site-packages\django\db\models\query.py", line 91, in __iter__
    results = compiler.execute_sql(
        chunked_fetch=self.chunked_fetch, chunk_size=self.chunk_size
    )
  File "C:\Users\A\Desktop\Digitall Skills\RH_App\venv\Lib\site-packages\django\db\models\sql\compiler.py", line 1562, in execute_sql
    cursor.execute(sql, params)
    ~~~~~~~~~~~~~~^^^^^^^^^^^^^
  File "C:\Users\A\Desktop\Digitall Skills\RH_App\venv\Lib\site-packages\django\db\backends\utils.py", line 122, in execute
    return super().execute(sql, params)
           ~~~~~~~~~~~~~~~^^^^^^^^^^^^^
  File "C:\Users\A\Desktop\Digitall Skills\RH_App\venv\Lib\site-packages\django\db\backends\utils.py", line 79, in execute
    return self._execute_with_wrappers(
           ~~~~~~~~~~~~~~~~~~~~~~~~~~~^
        sql, params, many=False, executor=self._execute
        ^^^^^^^^^^^^^^^^^^^^^^^^^^^^^^^^^^^^^^^^^^^^^^^
    )
    ^
  File "C:\Users\A\Desktop\Digitall Skills\RH_App\venv\Lib\site-packages\django\db\backends\utils.py", line 92, in _execute_with_wrappers
    return executor(sql, params, many, context)
  File "C:\Users\A\Desktop\Digitall Skills\RH_App\venv\Lib\site-packages\django\db\backends\utils.py", line 100, in _execute
    with self.db.wrap_database_errors:
         ^^^^^^^^^^^^^^^^^^^^^^^^^^^^
  File "C:\Users\A\Desktop\Digitall Skills\RH_App\venv\Lib\site-packages\django\db\utils.py", line 91, in __exit__
    raise dj_exc_value.with_traceback(traceback) from exc_value
  File "C:\Users\A\Desktop\Digitall Skills\RH_App\venv\Lib\site-packages\django\db\backends\utils.py", line 105, in _execute
    return self.cursor.execute(sql, params)
           ~~~~~~~~~~~~~~~~~~~^^^^^^^^^^^^^
  File "C:\Users\A\Desktop\Digitall Skills\RH_App\venv\Lib\site-packages\django\db\backends\sqlite3\base.py", line 328, in execute
    return super().execute(query, params)
           ~~~~~~~~~~~~~~~^^^^^^^^^^^^^^^
django.db.utils.OperationalError: no such table: users
ERROR 2025-08-23 23:16:22,566 basehttp 13140 8220 "POST /api/auth/login/ HTTP/1.1" 500 229596
ERROR 2025-08-23 23:17:09,902 log 13140 24408 Internal Server Error: /api/auth/login/
Traceback (most recent call last):
  File "C:\Users\A\Desktop\Digitall Skills\RH_App\venv\Lib\site-packages\django\db\backends\utils.py", line 105, in _execute
    return self.cursor.execute(sql, params)
           ~~~~~~~~~~~~~~~~~~~^^^^^^^^^^^^^
  File "C:\Users\A\Desktop\Digitall Skills\RH_App\venv\Lib\site-packages\django\db\backends\sqlite3\base.py", line 328, in execute
    return super().execute(query, params)
           ~~~~~~~~~~~~~~~^^^^^^^^^^^^^^^
sqlite3.OperationalError: no such table: users

The above exception was the direct cause of the following exception:

Traceback (most recent call last):
  File "C:\Users\A\Desktop\Digitall Skills\RH_App\venv\Lib\site-packages\django\core\handlers\exception.py", line 55, in inner
    response = get_response(request)
  File "C:\Users\A\Desktop\Digitall Skills\RH_App\venv\Lib\site-packages\django\core\handlers\base.py", line 197, in _get_response
    response = wrapped_callback(request, *callback_args, **callback_kwargs)
  File "C:\Users\A\Desktop\Digitall Skills\RH_App\venv\Lib\site-packages\django\views\decorators\csrf.py", line 65, in _view_wrapper
    return view_func(request, *args, **kwargs)
  File "C:\Users\A\Desktop\Digitall Skills\RH_App\venv\Lib\site-packages\django\views\generic\base.py", line 104, in view
    return self.dispatch(request, *args, **kwargs)
           ~~~~~~~~~~~~~^^^^^^^^^^^^^^^^^^^^^^^^^^
  File "C:\Users\A\Desktop\Digitall Skills\RH_App\venv\Lib\site-packages\rest_framework\views.py", line 509, in dispatch
    response = self.handle_exception(exc)
  File "C:\Users\A\Desktop\Digitall Skills\RH_App\venv\Lib\site-packages\rest_framework\views.py", line 469, in handle_exception
    self.raise_uncaught_exception(exc)
    ~~~~~~~~~~~~~~~~~~~~~~~~~~~~~^^^^^
  File "C:\Users\A\Desktop\Digitall Skills\RH_App\venv\Lib\site-packages\rest_framework\views.py", line 480, in raise_uncaught_exception
    raise exc
  File "C:\Users\A\Desktop\Digitall Skills\RH_App\venv\Lib\site-packages\rest_framework\views.py", line 506, in dispatch
    response = handler(request, *args, **kwargs)
  File "C:\Users\A\Desktop\Digitall Skills\RH_App\venv\Lib\site-packages\rest_framework_simplejwt\views.py", line 46, in post
    serializer.is_valid(raise_exception=True)
    ~~~~~~~~~~~~~~~~~~~^^^^^^^^^^^^^^^^^^^^^^
  File "C:\Users\A\Desktop\Digitall Skills\RH_App\venv\Lib\site-packages\rest_framework\serializers.py", line 227, in is_valid
    self._validated_data = self.run_validation(self.initial_data)
                           ~~~~~~~~~~~~~~~~~~~^^^^^^^^^^^^^^^^^^^
  File "C:\Users\A\Desktop\Digitall Skills\RH_App\venv\Lib\site-packages\rest_framework\serializers.py", line 429, in run_validation
    value = self.validate(value)
  File "C:\Users\A\Desktop\Digitall Skills\RH_App\venv\Lib\site-packages\rest_framework_simplejwt\serializers.py", line 73, in validate
    data = super().validate(attrs)
  File "C:\Users\A\Desktop\Digitall Skills\RH_App\venv\Lib\site-packages\rest_framework_simplejwt\serializers.py", line 54, in validate
    self.user = authenticate(**authenticate_kwargs)
                ~~~~~~~~~~~~^^^^^^^^^^^^^^^^^^^^^^^
  File "C:\Users\A\Desktop\Digitall Skills\RH_App\venv\Lib\site-packages\django\views\decorators\debug.py", line 73, in sensitive_variables_wrapper
    return func(*func_args, **func_kwargs)
  File "C:\Users\A\Desktop\Digitall Skills\RH_App\venv\Lib\site-packages\django\contrib\auth\__init__.py", line 79, in authenticate
    user = backend.authenticate(request, **credentials)
  File "C:\Users\A\Desktop\Digitall Skills\RH_App\venv\Lib\site-packages\django\contrib\auth\backends.py", line 42, in authenticate
    user = UserModel._default_manager.get_by_natural_key(username)
  File "C:\Users\A\Desktop\Digitall Skills\RH_App\venv\Lib\site-packages\django\contrib\auth\base_user.py", line 55, in get_by_natural_key
    return self.get(**{self.model.USERNAME_FIELD: username})
           ~~~~~~~~^^^^^^^^^^^^^^^^^^^^^^^^^^^^^^^^^^^^^^^^^
  File "C:\Users\A\Desktop\Digitall Skills\RH_App\venv\Lib\site-packages\django\db\models\manager.py", line 87, in manager_method
    return getattr(self.get_queryset(), name)(*args, **kwargs)
           ~~~~~~~~~~~~~~~~~~~~~~~~~~~~~~~~~~^^^^^^^^^^^^^^^^^
  File "C:\Users\A\Desktop\Digitall Skills\RH_App\venv\Lib\site-packages\django\db\models\query.py", line 643, in get
    num = len(clone)
  File "C:\Users\A\Desktop\Digitall Skills\RH_App\venv\Lib\site-packages\django\db\models\query.py", line 380, in __len__
    self._fetch_all()
    ~~~~~~~~~~~~~~~^^
  File "C:\Users\A\Desktop\Digitall Skills\RH_App\venv\Lib\site-packages\django\db\models\query.py", line 1926, in _fetch_all
    self._result_cache = list(self._iterable_class(self))
                         ~~~~^^^^^^^^^^^^^^^^^^^^^^^^^^^^
  File "C:\Users\A\Desktop\Digitall Skills\RH_App\venv\Lib\site-packages\django\db\models\query.py", line 91, in __iter__
    results = compiler.execute_sql(
        chunked_fetch=self.chunked_fetch, chunk_size=self.chunk_size
    )
  File "C:\Users\A\Desktop\Digitall Skills\RH_App\venv\Lib\site-packages\django\db\models\sql\compiler.py", line 1562, in execute_sql
    cursor.execute(sql, params)
    ~~~~~~~~~~~~~~^^^^^^^^^^^^^
  File "C:\Users\A\Desktop\Digitall Skills\RH_App\venv\Lib\site-packages\django\db\backends\utils.py", line 122, in execute
    return super().execute(sql, params)
           ~~~~~~~~~~~~~~~^^^^^^^^^^^^^
  File "C:\Users\A\Desktop\Digitall Skills\RH_App\venv\Lib\site-packages\django\db\backends\utils.py", line 79, in execute
    return self._execute_with_wrappers(
           ~~~~~~~~~~~~~~~~~~~~~~~~~~~^
        sql, params, many=False, executor=self._execute
        ^^^^^^^^^^^^^^^^^^^^^^^^^^^^^^^^^^^^^^^^^^^^^^^
    )
    ^
  File "C:\Users\A\Desktop\Digitall Skills\RH_App\venv\Lib\site-packages\django\db\backends\utils.py", line 92, in _execute_with_wrappers
    return executor(sql, params, many, context)
  File "C:\Users\A\Desktop\Digitall Skills\RH_App\venv\Lib\site-packages\django\db\backends\utils.py", line 100, in _execute
    with self.db.wrap_database_errors:
         ^^^^^^^^^^^^^^^^^^^^^^^^^^^^
  File "C:\Users\A\Desktop\Digitall Skills\RH_App\venv\Lib\site-packages\django\db\utils.py", line 91, in __exit__
    raise dj_exc_value.with_traceback(traceback) from exc_value
  File "C:\Users\A\Desktop\Digitall Skills\RH_App\venv\Lib\site-packages\django\db\backends\utils.py", line 105, in _execute
    return self.cursor.execute(sql, params)
           ~~~~~~~~~~~~~~~~~~~^^^^^^^^^^^^^
  File "C:\Users\A\Desktop\Digitall Skills\RH_App\venv\Lib\site-packages\django\db\backends\sqlite3\base.py", line 328, in execute
    return super().execute(query, params)
           ~~~~~~~~~~~~~~~^^^^^^^^^^^^^^^
django.db.utils.OperationalError: no such table: users
ERROR 2025-08-23 23:17:09,914 basehttp 13140 24408 "POST /api/auth/login/ HTTP/1.1" 500 229747
ERROR 2025-08-23 23:17:18,232 log 13140 24408 Internal Server Error: /api/auth/login/
Traceback (most recent call last):
  File "C:\Users\A\Desktop\Digitall Skills\RH_App\venv\Lib\site-packages\django\db\backends\utils.py", line 105, in _execute
    return self.cursor.execute(sql, params)
           ~~~~~~~~~~~~~~~~~~~^^^^^^^^^^^^^
  File "C:\Users\A\Desktop\Digitall Skills\RH_App\venv\Lib\site-packages\django\db\backends\sqlite3\base.py", line 328, in execute
    return super().execute(query, params)
           ~~~~~~~~~~~~~~~^^^^^^^^^^^^^^^
sqlite3.OperationalError: no such table: users

The above exception was the direct cause of the following exception:

Traceback (most recent call last):
  File "C:\Users\A\Desktop\Digitall Skills\RH_App\venv\Lib\site-packages\django\core\handlers\exception.py", line 55, in inner
    response = get_response(request)
  File "C:\Users\A\Desktop\Digitall Skills\RH_App\venv\Lib\site-packages\django\core\handlers\base.py", line 197, in _get_response
    response = wrapped_callback(request, *callback_args, **callback_kwargs)
  File "C:\Users\A\Desktop\Digitall Skills\RH_App\venv\Lib\site-packages\django\views\decorators\csrf.py", line 65, in _view_wrapper
    return view_func(request, *args, **kwargs)
  File "C:\Users\A\Desktop\Digitall Skills\RH_App\venv\Lib\site-packages\django\views\generic\base.py", line 104, in view
    return self.dispatch(request, *args, **kwargs)
           ~~~~~~~~~~~~~^^^^^^^^^^^^^^^^^^^^^^^^^^
  File "C:\Users\A\Desktop\Digitall Skills\RH_App\venv\Lib\site-packages\rest_framework\views.py", line 509, in dispatch
    response = self.handle_exception(exc)
  File "C:\Users\A\Desktop\Digitall Skills\RH_App\venv\Lib\site-packages\rest_framework\views.py", line 469, in handle_exception
    self.raise_uncaught_exception(exc)
    ~~~~~~~~~~~~~~~~~~~~~~~~~~~~~^^^^^
  File "C:\Users\A\Desktop\Digitall Skills\RH_App\venv\Lib\site-packages\rest_framework\views.py", line 480, in raise_uncaught_exception
    raise exc
  File "C:\Users\A\Desktop\Digitall Skills\RH_App\venv\Lib\site-packages\rest_framework\views.py", line 506, in dispatch
    response = handler(request, *args, **kwargs)
  File "C:\Users\A\Desktop\Digitall Skills\RH_App\venv\Lib\site-packages\rest_framework_simplejwt\views.py", line 46, in post
    serializer.is_valid(raise_exception=True)
    ~~~~~~~~~~~~~~~~~~~^^^^^^^^^^^^^^^^^^^^^^
  File "C:\Users\A\Desktop\Digitall Skills\RH_App\venv\Lib\site-packages\rest_framework\serializers.py", line 227, in is_valid
    self._validated_data = self.run_validation(self.initial_data)
                           ~~~~~~~~~~~~~~~~~~~^^^^^^^^^^^^^^^^^^^
  File "C:\Users\A\Desktop\Digitall Skills\RH_App\venv\Lib\site-packages\rest_framework\serializers.py", line 429, in run_validation
    value = self.validate(value)
  File "C:\Users\A\Desktop\Digitall Skills\RH_App\venv\Lib\site-packages\rest_framework_simplejwt\serializers.py", line 73, in validate
    data = super().validate(attrs)
  File "C:\Users\A\Desktop\Digitall Skills\RH_App\venv\Lib\site-packages\rest_framework_simplejwt\serializers.py", line 54, in validate
    self.user = authenticate(**authenticate_kwargs)
                ~~~~~~~~~~~~^^^^^^^^^^^^^^^^^^^^^^^
  File "C:\Users\A\Desktop\Digitall Skills\RH_App\venv\Lib\site-packages\django\views\decorators\debug.py", line 73, in sensitive_variables_wrapper
    return func(*func_args, **func_kwargs)
  File "C:\Users\A\Desktop\Digitall Skills\RH_App\venv\Lib\site-packages\django\contrib\auth\__init__.py", line 79, in authenticate
    user = backend.authenticate(request, **credentials)
  File "C:\Users\A\Desktop\Digitall Skills\RH_App\venv\Lib\site-packages\django\contrib\auth\backends.py", line 42, in authenticate
    user = UserModel._default_manager.get_by_natural_key(username)
  File "C:\Users\A\Desktop\Digitall Skills\RH_App\venv\Lib\site-packages\django\contrib\auth\base_user.py", line 55, in get_by_natural_key
    return self.get(**{self.model.USERNAME_FIELD: username})
           ~~~~~~~~^^^^^^^^^^^^^^^^^^^^^^^^^^^^^^^^^^^^^^^^^
  File "C:\Users\A\Desktop\Digitall Skills\RH_App\venv\Lib\site-packages\django\db\models\manager.py", line 87, in manager_method
    return getattr(self.get_queryset(), name)(*args, **kwargs)
           ~~~~~~~~~~~~~~~~~~~~~~~~~~~~~~~~~~^^^^^^^^^^^^^^^^^
  File "C:\Users\A\Desktop\Digitall Skills\RH_App\venv\Lib\site-packages\django\db\models\query.py", line 643, in get
    num = len(clone)
  File "C:\Users\A\Desktop\Digitall Skills\RH_App\venv\Lib\site-packages\django\db\models\query.py", line 380, in __len__
    self._fetch_all()
    ~~~~~~~~~~~~~~~^^
  File "C:\Users\A\Desktop\Digitall Skills\RH_App\venv\Lib\site-packages\django\db\models\query.py", line 1926, in _fetch_all
    self._result_cache = list(self._iterable_class(self))
                         ~~~~^^^^^^^^^^^^^^^^^^^^^^^^^^^^
  File "C:\Users\A\Desktop\Digitall Skills\RH_App\venv\Lib\site-packages\django\db\models\query.py", line 91, in __iter__
    results = compiler.execute_sql(
        chunked_fetch=self.chunked_fetch, chunk_size=self.chunk_size
    )
  File "C:\Users\A\Desktop\Digitall Skills\RH_App\venv\Lib\site-packages\django\db\models\sql\compiler.py", line 1562, in execute_sql
    cursor.execute(sql, params)
    ~~~~~~~~~~~~~~^^^^^^^^^^^^^
  File "C:\Users\A\Desktop\Digitall Skills\RH_App\venv\Lib\site-packages\django\db\backends\utils.py", line 122, in execute
    return super().execute(sql, params)
           ~~~~~~~~~~~~~~~^^^^^^^^^^^^^
  File "C:\Users\A\Desktop\Digitall Skills\RH_App\venv\Lib\site-packages\django\db\backends\utils.py", line 79, in execute
    return self._execute_with_wrappers(
           ~~~~~~~~~~~~~~~~~~~~~~~~~~~^
        sql, params, many=False, executor=self._execute
        ^^^^^^^^^^^^^^^^^^^^^^^^^^^^^^^^^^^^^^^^^^^^^^^
    )
    ^
  File "C:\Users\A\Desktop\Digitall Skills\RH_App\venv\Lib\site-packages\django\db\backends\utils.py", line 92, in _execute_with_wrappers
    return executor(sql, params, many, context)
  File "C:\Users\A\Desktop\Digitall Skills\RH_App\venv\Lib\site-packages\django\db\backends\utils.py", line 100, in _execute
    with self.db.wrap_database_errors:
         ^^^^^^^^^^^^^^^^^^^^^^^^^^^^
  File "C:\Users\A\Desktop\Digitall Skills\RH_App\venv\Lib\site-packages\django\db\utils.py", line 91, in __exit__
    raise dj_exc_value.with_traceback(traceback) from exc_value
  File "C:\Users\A\Desktop\Digitall Skills\RH_App\venv\Lib\site-packages\django\db\backends\utils.py", line 105, in _execute
    return self.cursor.execute(sql, params)
           ~~~~~~~~~~~~~~~~~~~^^^^^^^^^^^^^
  File "C:\Users\A\Desktop\Digitall Skills\RH_App\venv\Lib\site-packages\django\db\backends\sqlite3\base.py", line 328, in execute
    return super().execute(query, params)
           ~~~~~~~~~~~~~~~^^^^^^^^^^^^^^^
django.db.utils.OperationalError: no such table: users
ERROR 2025-08-23 23:17:18,244 basehttp 13140 24408 "POST /api/auth/login/ HTTP/1.1" 500 229747
ERROR 2025-08-23 23:17:28,490 log 13140 24408 Internal Server Error: /api/auth/login/
Traceback (most recent call last):
  File "C:\Users\A\Desktop\Digitall Skills\RH_App\venv\Lib\site-packages\django\db\backends\utils.py", line 105, in _execute
    return self.cursor.execute(sql, params)
           ~~~~~~~~~~~~~~~~~~~^^^^^^^^^^^^^
  File "C:\Users\A\Desktop\Digitall Skills\RH_App\venv\Lib\site-packages\django\db\backends\sqlite3\base.py", line 328, in execute
    return super().execute(query, params)
           ~~~~~~~~~~~~~~~^^^^^^^^^^^^^^^
sqlite3.OperationalError: no such table: users

The above exception was the direct cause of the following exception:

Traceback (most recent call last):
  File "C:\Users\A\Desktop\Digitall Skills\RH_App\venv\Lib\site-packages\django\core\handlers\exception.py", line 55, in inner
    response = get_response(request)
  File "C:\Users\A\Desktop\Digitall Skills\RH_App\venv\Lib\site-packages\django\core\handlers\base.py", line 197, in _get_response
    response = wrapped_callback(request, *callback_args, **callback_kwargs)
  File "C:\Users\A\Desktop\Digitall Skills\RH_App\venv\Lib\site-packages\django\views\decorators\csrf.py", line 65, in _view_wrapper
    return view_func(request, *args, **kwargs)
  File "C:\Users\A\Desktop\Digitall Skills\RH_App\venv\Lib\site-packages\django\views\generic\base.py", line 104, in view
    return self.dispatch(request, *args, **kwargs)
           ~~~~~~~~~~~~~^^^^^^^^^^^^^^^^^^^^^^^^^^
  File "C:\Users\A\Desktop\Digitall Skills\RH_App\venv\Lib\site-packages\rest_framework\views.py", line 509, in dispatch
    response = self.handle_exception(exc)
  File "C:\Users\A\Desktop\Digitall Skills\RH_App\venv\Lib\site-packages\rest_framework\views.py", line 469, in handle_exception
    self.raise_uncaught_exception(exc)
    ~~~~~~~~~~~~~~~~~~~~~~~~~~~~~^^^^^
  File "C:\Users\A\Desktop\Digitall Skills\RH_App\venv\Lib\site-packages\rest_framework\views.py", line 480, in raise_uncaught_exception
    raise exc
  File "C:\Users\A\Desktop\Digitall Skills\RH_App\venv\Lib\site-packages\rest_framework\views.py", line 506, in dispatch
    response = handler(request, *args, **kwargs)
  File "C:\Users\A\Desktop\Digitall Skills\RH_App\venv\Lib\site-packages\rest_framework_simplejwt\views.py", line 46, in post
    serializer.is_valid(raise_exception=True)
    ~~~~~~~~~~~~~~~~~~~^^^^^^^^^^^^^^^^^^^^^^
  File "C:\Users\A\Desktop\Digitall Skills\RH_App\venv\Lib\site-packages\rest_framework\serializers.py", line 227, in is_valid
    self._validated_data = self.run_validation(self.initial_data)
                           ~~~~~~~~~~~~~~~~~~~^^^^^^^^^^^^^^^^^^^
  File "C:\Users\A\Desktop\Digitall Skills\RH_App\venv\Lib\site-packages\rest_framework\serializers.py", line 429, in run_validation
    value = self.validate(value)
  File "C:\Users\A\Desktop\Digitall Skills\RH_App\venv\Lib\site-packages\rest_framework_simplejwt\serializers.py", line 73, in validate
    data = super().validate(attrs)
  File "C:\Users\A\Desktop\Digitall Skills\RH_App\venv\Lib\site-packages\rest_framework_simplejwt\serializers.py", line 54, in validate
    self.user = authenticate(**authenticate_kwargs)
                ~~~~~~~~~~~~^^^^^^^^^^^^^^^^^^^^^^^
  File "C:\Users\A\Desktop\Digitall Skills\RH_App\venv\Lib\site-packages\django\views\decorators\debug.py", line 73, in sensitive_variables_wrapper
    return func(*func_args, **func_kwargs)
  File "C:\Users\A\Desktop\Digitall Skills\RH_App\venv\Lib\site-packages\django\contrib\auth\__init__.py", line 79, in authenticate
    user = backend.authenticate(request, **credentials)
  File "C:\Users\A\Desktop\Digitall Skills\RH_App\venv\Lib\site-packages\django\contrib\auth\backends.py", line 42, in authenticate
    user = UserModel._default_manager.get_by_natural_key(username)
  File "C:\Users\A\Desktop\Digitall Skills\RH_App\venv\Lib\site-packages\django\contrib\auth\base_user.py", line 55, in get_by_natural_key
    return self.get(**{self.model.USERNAME_FIELD: username})
           ~~~~~~~~^^^^^^^^^^^^^^^^^^^^^^^^^^^^^^^^^^^^^^^^^
  File "C:\Users\A\Desktop\Digitall Skills\RH_App\venv\Lib\site-packages\django\db\models\manager.py", line 87, in manager_method
    return getattr(self.get_queryset(), name)(*args, **kwargs)
           ~~~~~~~~~~~~~~~~~~~~~~~~~~~~~~~~~~^^^^^^^^^^^^^^^^^
  File "C:\Users\A\Desktop\Digitall Skills\RH_App\venv\Lib\site-packages\django\db\models\query.py", line 643, in get
    num = len(clone)
  File "C:\Users\A\Desktop\Digitall Skills\RH_App\venv\Lib\site-packages\django\db\models\query.py", line 380, in __len__
    self._fetch_all()
    ~~~~~~~~~~~~~~~^^
  File "C:\Users\A\Desktop\Digitall Skills\RH_App\venv\Lib\site-packages\django\db\models\query.py", line 1926, in _fetch_all
    self._result_cache = list(self._iterable_class(self))
                         ~~~~^^^^^^^^^^^^^^^^^^^^^^^^^^^^
  File "C:\Users\A\Desktop\Digitall Skills\RH_App\venv\Lib\site-packages\django\db\models\query.py", line 91, in __iter__
    results = compiler.execute_sql(
        chunked_fetch=self.chunked_fetch, chunk_size=self.chunk_size
    )
  File "C:\Users\A\Desktop\Digitall Skills\RH_App\venv\Lib\site-packages\django\db\models\sql\compiler.py", line 1562, in execute_sql
    cursor.execute(sql, params)
    ~~~~~~~~~~~~~~^^^^^^^^^^^^^
  File "C:\Users\A\Desktop\Digitall Skills\RH_App\venv\Lib\site-packages\django\db\backends\utils.py", line 122, in execute
    return super().execute(sql, params)
           ~~~~~~~~~~~~~~~^^^^^^^^^^^^^
  File "C:\Users\A\Desktop\Digitall Skills\RH_App\venv\Lib\site-packages\django\db\backends\utils.py", line 79, in execute
    return self._execute_with_wrappers(
           ~~~~~~~~~~~~~~~~~~~~~~~~~~~^
        sql, params, many=False, executor=self._execute
        ^^^^^^^^^^^^^^^^^^^^^^^^^^^^^^^^^^^^^^^^^^^^^^^
    )
    ^
  File "C:\Users\A\Desktop\Digitall Skills\RH_App\venv\Lib\site-packages\django\db\backends\utils.py", line 92, in _execute_with_wrappers
    return executor(sql, params, many, context)
  File "C:\Users\A\Desktop\Digitall Skills\RH_App\venv\Lib\site-packages\django\db\backends\utils.py", line 100, in _execute
    with self.db.wrap_database_errors:
         ^^^^^^^^^^^^^^^^^^^^^^^^^^^^
  File "C:\Users\A\Desktop\Digitall Skills\RH_App\venv\Lib\site-packages\django\db\utils.py", line 91, in __exit__
    raise dj_exc_value.with_traceback(traceback) from exc_value
  File "C:\Users\A\Desktop\Digitall Skills\RH_App\venv\Lib\site-packages\django\db\backends\utils.py", line 105, in _execute
    return self.cursor.execute(sql, params)
           ~~~~~~~~~~~~~~~~~~~^^^^^^^^^^^^^
  File "C:\Users\A\Desktop\Digitall Skills\RH_App\venv\Lib\site-packages\django\db\backends\sqlite3\base.py", line 328, in execute
    return super().execute(query, params)
           ~~~~~~~~~~~~~~~^^^^^^^^^^^^^^^
django.db.utils.OperationalError: no such table: users
ERROR 2025-08-23 23:17:28,510 basehttp 13140 24408 "POST /api/auth/login/ HTTP/1.1" 500 229572
ERROR 2025-08-23 23:17:30,466 log 13140 24408 Internal Server Error: /api/auth/login/
Traceback (most recent call last):
  File "C:\Users\A\Desktop\Digitall Skills\RH_App\venv\Lib\site-packages\django\db\backends\utils.py", line 105, in _execute
    return self.cursor.execute(sql, params)
           ~~~~~~~~~~~~~~~~~~~^^^^^^^^^^^^^
  File "C:\Users\A\Desktop\Digitall Skills\RH_App\venv\Lib\site-packages\django\db\backends\sqlite3\base.py", line 328, in execute
    return super().execute(query, params)
           ~~~~~~~~~~~~~~~^^^^^^^^^^^^^^^
sqlite3.OperationalError: no such table: users

The above exception was the direct cause of the following exception:

Traceback (most recent call last):
  File "C:\Users\A\Desktop\Digitall Skills\RH_App\venv\Lib\site-packages\django\core\handlers\exception.py", line 55, in inner
    response = get_response(request)
  File "C:\Users\A\Desktop\Digitall Skills\RH_App\venv\Lib\site-packages\django\core\handlers\base.py", line 197, in _get_response
    response = wrapped_callback(request, *callback_args, **callback_kwargs)
  File "C:\Users\A\Desktop\Digitall Skills\RH_App\venv\Lib\site-packages\django\views\decorators\csrf.py", line 65, in _view_wrapper
    return view_func(request, *args, **kwargs)
  File "C:\Users\A\Desktop\Digitall Skills\RH_App\venv\Lib\site-packages\django\views\generic\base.py", line 104, in view
    return self.dispatch(request, *args, **kwargs)
           ~~~~~~~~~~~~~^^^^^^^^^^^^^^^^^^^^^^^^^^
  File "C:\Users\A\Desktop\Digitall Skills\RH_App\venv\Lib\site-packages\rest_framework\views.py", line 509, in dispatch
    response = self.handle_exception(exc)
  File "C:\Users\A\Desktop\Digitall Skills\RH_App\venv\Lib\site-packages\rest_framework\views.py", line 469, in handle_exception
    self.raise_uncaught_exception(exc)
    ~~~~~~~~~~~~~~~~~~~~~~~~~~~~~^^^^^
  File "C:\Users\A\Desktop\Digitall Skills\RH_App\venv\Lib\site-packages\rest_framework\views.py", line 480, in raise_uncaught_exception
    raise exc
  File "C:\Users\A\Desktop\Digitall Skills\RH_App\venv\Lib\site-packages\rest_framework\views.py", line 506, in dispatch
    response = handler(request, *args, **kwargs)
  File "C:\Users\A\Desktop\Digitall Skills\RH_App\venv\Lib\site-packages\rest_framework_simplejwt\views.py", line 46, in post
    serializer.is_valid(raise_exception=True)
    ~~~~~~~~~~~~~~~~~~~^^^^^^^^^^^^^^^^^^^^^^
  File "C:\Users\A\Desktop\Digitall Skills\RH_App\venv\Lib\site-packages\rest_framework\serializers.py", line 227, in is_valid
    self._validated_data = self.run_validation(self.initial_data)
                           ~~~~~~~~~~~~~~~~~~~^^^^^^^^^^^^^^^^^^^
  File "C:\Users\A\Desktop\Digitall Skills\RH_App\venv\Lib\site-packages\rest_framework\serializers.py", line 429, in run_validation
    value = self.validate(value)
  File "C:\Users\A\Desktop\Digitall Skills\RH_App\venv\Lib\site-packages\rest_framework_simplejwt\serializers.py", line 73, in validate
    data = super().validate(attrs)
  File "C:\Users\A\Desktop\Digitall Skills\RH_App\venv\Lib\site-packages\rest_framework_simplejwt\serializers.py", line 54, in validate
    self.user = authenticate(**authenticate_kwargs)
                ~~~~~~~~~~~~^^^^^^^^^^^^^^^^^^^^^^^
  File "C:\Users\A\Desktop\Digitall Skills\RH_App\venv\Lib\site-packages\django\views\decorators\debug.py", line 73, in sensitive_variables_wrapper
    return func(*func_args, **func_kwargs)
  File "C:\Users\A\Desktop\Digitall Skills\RH_App\venv\Lib\site-packages\django\contrib\auth\__init__.py", line 79, in authenticate
    user = backend.authenticate(request, **credentials)
  File "C:\Users\A\Desktop\Digitall Skills\RH_App\venv\Lib\site-packages\django\contrib\auth\backends.py", line 42, in authenticate
    user = UserModel._default_manager.get_by_natural_key(username)
  File "C:\Users\A\Desktop\Digitall Skills\RH_App\venv\Lib\site-packages\django\contrib\auth\base_user.py", line 55, in get_by_natural_key
    return self.get(**{self.model.USERNAME_FIELD: username})
           ~~~~~~~~^^^^^^^^^^^^^^^^^^^^^^^^^^^^^^^^^^^^^^^^^
  File "C:\Users\A\Desktop\Digitall Skills\RH_App\venv\Lib\site-packages\django\db\models\manager.py", line 87, in manager_method
    return getattr(self.get_queryset(), name)(*args, **kwargs)
           ~~~~~~~~~~~~~~~~~~~~~~~~~~~~~~~~~~^^^^^^^^^^^^^^^^^
  File "C:\Users\A\Desktop\Digitall Skills\RH_App\venv\Lib\site-packages\django\db\models\query.py", line 643, in get
    num = len(clone)
  File "C:\Users\A\Desktop\Digitall Skills\RH_App\venv\Lib\site-packages\django\db\models\query.py", line 380, in __len__
    self._fetch_all()
    ~~~~~~~~~~~~~~~^^
  File "C:\Users\A\Desktop\Digitall Skills\RH_App\venv\Lib\site-packages\django\db\models\query.py", line 1926, in _fetch_all
    self._result_cache = list(self._iterable_class(self))
                         ~~~~^^^^^^^^^^^^^^^^^^^^^^^^^^^^
  File "C:\Users\A\Desktop\Digitall Skills\RH_App\venv\Lib\site-packages\django\db\models\query.py", line 91, in __iter__
    results = compiler.execute_sql(
        chunked_fetch=self.chunked_fetch, chunk_size=self.chunk_size
    )
  File "C:\Users\A\Desktop\Digitall Skills\RH_App\venv\Lib\site-packages\django\db\models\sql\compiler.py", line 1562, in execute_sql
    cursor.execute(sql, params)
    ~~~~~~~~~~~~~~^^^^^^^^^^^^^
  File "C:\Users\A\Desktop\Digitall Skills\RH_App\venv\Lib\site-packages\django\db\backends\utils.py", line 122, in execute
    return super().execute(sql, params)
           ~~~~~~~~~~~~~~~^^^^^^^^^^^^^
  File "C:\Users\A\Desktop\Digitall Skills\RH_App\venv\Lib\site-packages\django\db\backends\utils.py", line 79, in execute
    return self._execute_with_wrappers(
           ~~~~~~~~~~~~~~~~~~~~~~~~~~~^
        sql, params, many=False, executor=self._execute
        ^^^^^^^^^^^^^^^^^^^^^^^^^^^^^^^^^^^^^^^^^^^^^^^
    )
    ^
  File "C:\Users\A\Desktop\Digitall Skills\RH_App\venv\Lib\site-packages\django\db\backends\utils.py", line 92, in _execute_with_wrappers
    return executor(sql, params, many, context)
  File "C:\Users\A\Desktop\Digitall Skills\RH_App\venv\Lib\site-packages\django\db\backends\utils.py", line 100, in _execute
    with self.db.wrap_database_errors:
         ^^^^^^^^^^^^^^^^^^^^^^^^^^^^
  File "C:\Users\A\Desktop\Digitall Skills\RH_App\venv\Lib\site-packages\django\db\utils.py", line 91, in __exit__
    raise dj_exc_value.with_traceback(traceback) from exc_value
  File "C:\Users\A\Desktop\Digitall Skills\RH_App\venv\Lib\site-packages\django\db\backends\utils.py", line 105, in _execute
    return self.cursor.execute(sql, params)
           ~~~~~~~~~~~~~~~~~~~^^^^^^^^^^^^^
  File "C:\Users\A\Desktop\Digitall Skills\RH_App\venv\Lib\site-packages\django\db\backends\sqlite3\base.py", line 328, in execute
    return super().execute(query, params)
           ~~~~~~~~~~~~~~~^^^^^^^^^^^^^^^
django.db.utils.OperationalError: no such table: users
ERROR 2025-08-23 23:17:30,524 basehttp 13140 24408 "POST /api/auth/login/ HTTP/1.1" 500 229572
ERROR 2025-08-23 23:17:31,688 log 13140 24408 Internal Server Error: /api/auth/login/
Traceback (most recent call last):
  File "C:\Users\A\Desktop\Digitall Skills\RH_App\venv\Lib\site-packages\django\db\backends\utils.py", line 105, in _execute
    return self.cursor.execute(sql, params)
           ~~~~~~~~~~~~~~~~~~~^^^^^^^^^^^^^
  File "C:\Users\A\Desktop\Digitall Skills\RH_App\venv\Lib\site-packages\django\db\backends\sqlite3\base.py", line 328, in execute
    return super().execute(query, params)
           ~~~~~~~~~~~~~~~^^^^^^^^^^^^^^^
sqlite3.OperationalError: no such table: users

The above exception was the direct cause of the following exception:

Traceback (most recent call last):
  File "C:\Users\A\Desktop\Digitall Skills\RH_App\venv\Lib\site-packages\django\core\handlers\exception.py", line 55, in inner
    response = get_response(request)
  File "C:\Users\A\Desktop\Digitall Skills\RH_App\venv\Lib\site-packages\django\core\handlers\base.py", line 197, in _get_response
    response = wrapped_callback(request, *callback_args, **callback_kwargs)
  File "C:\Users\A\Desktop\Digitall Skills\RH_App\venv\Lib\site-packages\django\views\decorators\csrf.py", line 65, in _view_wrapper
    return view_func(request, *args, **kwargs)
  File "C:\Users\A\Desktop\Digitall Skills\RH_App\venv\Lib\site-packages\django\views\generic\base.py", line 104, in view
    return self.dispatch(request, *args, **kwargs)
           ~~~~~~~~~~~~~^^^^^^^^^^^^^^^^^^^^^^^^^^
  File "C:\Users\A\Desktop\Digitall Skills\RH_App\venv\Lib\site-packages\rest_framework\views.py", line 509, in dispatch
    response = self.handle_exception(exc)
  File "C:\Users\A\Desktop\Digitall Skills\RH_App\venv\Lib\site-packages\rest_framework\views.py", line 469, in handle_exception
    self.raise_uncaught_exception(exc)
    ~~~~~~~~~~~~~~~~~~~~~~~~~~~~~^^^^^
  File "C:\Users\A\Desktop\Digitall Skills\RH_App\venv\Lib\site-packages\rest_framework\views.py", line 480, in raise_uncaught_exception
    raise exc
  File "C:\Users\A\Desktop\Digitall Skills\RH_App\venv\Lib\site-packages\rest_framework\views.py", line 506, in dispatch
    response = handler(request, *args, **kwargs)
  File "C:\Users\A\Desktop\Digitall Skills\RH_App\venv\Lib\site-packages\rest_framework_simplejwt\views.py", line 46, in post
    serializer.is_valid(raise_exception=True)
    ~~~~~~~~~~~~~~~~~~~^^^^^^^^^^^^^^^^^^^^^^
  File "C:\Users\A\Desktop\Digitall Skills\RH_App\venv\Lib\site-packages\rest_framework\serializers.py", line 227, in is_valid
    self._validated_data = self.run_validation(self.initial_data)
                           ~~~~~~~~~~~~~~~~~~~^^^^^^^^^^^^^^^^^^^
  File "C:\Users\A\Desktop\Digitall Skills\RH_App\venv\Lib\site-packages\rest_framework\serializers.py", line 429, in run_validation
    value = self.validate(value)
  File "C:\Users\A\Desktop\Digitall Skills\RH_App\venv\Lib\site-packages\rest_framework_simplejwt\serializers.py", line 73, in validate
    data = super().validate(attrs)
  File "C:\Users\A\Desktop\Digitall Skills\RH_App\venv\Lib\site-packages\rest_framework_simplejwt\serializers.py", line 54, in validate
    self.user = authenticate(**authenticate_kwargs)
                ~~~~~~~~~~~~^^^^^^^^^^^^^^^^^^^^^^^
  File "C:\Users\A\Desktop\Digitall Skills\RH_App\venv\Lib\site-packages\django\views\decorators\debug.py", line 73, in sensitive_variables_wrapper
    return func(*func_args, **func_kwargs)
  File "C:\Users\A\Desktop\Digitall Skills\RH_App\venv\Lib\site-packages\django\contrib\auth\__init__.py", line 79, in authenticate
    user = backend.authenticate(request, **credentials)
  File "C:\Users\A\Desktop\Digitall Skills\RH_App\venv\Lib\site-packages\django\contrib\auth\backends.py", line 42, in authenticate
    user = UserModel._default_manager.get_by_natural_key(username)
  File "C:\Users\A\Desktop\Digitall Skills\RH_App\venv\Lib\site-packages\django\contrib\auth\base_user.py", line 55, in get_by_natural_key
    return self.get(**{self.model.USERNAME_FIELD: username})
           ~~~~~~~~^^^^^^^^^^^^^^^^^^^^^^^^^^^^^^^^^^^^^^^^^
  File "C:\Users\A\Desktop\Digitall Skills\RH_App\venv\Lib\site-packages\django\db\models\manager.py", line 87, in manager_method
    return getattr(self.get_queryset(), name)(*args, **kwargs)
           ~~~~~~~~~~~~~~~~~~~~~~~~~~~~~~~~~~^^^^^^^^^^^^^^^^^
  File "C:\Users\A\Desktop\Digitall Skills\RH_App\venv\Lib\site-packages\django\db\models\query.py", line 643, in get
    num = len(clone)
  File "C:\Users\A\Desktop\Digitall Skills\RH_App\venv\Lib\site-packages\django\db\models\query.py", line 380, in __len__
    self._fetch_all()
    ~~~~~~~~~~~~~~~^^
  File "C:\Users\A\Desktop\Digitall Skills\RH_App\venv\Lib\site-packages\django\db\models\query.py", line 1926, in _fetch_all
    self._result_cache = list(self._iterable_class(self))
                         ~~~~^^^^^^^^^^^^^^^^^^^^^^^^^^^^
  File "C:\Users\A\Desktop\Digitall Skills\RH_App\venv\Lib\site-packages\django\db\models\query.py", line 91, in __iter__
    results = compiler.execute_sql(
        chunked_fetch=self.chunked_fetch, chunk_size=self.chunk_size
    )
  File "C:\Users\A\Desktop\Digitall Skills\RH_App\venv\Lib\site-packages\django\db\models\sql\compiler.py", line 1562, in execute_sql
    cursor.execute(sql, params)
    ~~~~~~~~~~~~~~^^^^^^^^^^^^^
  File "C:\Users\A\Desktop\Digitall Skills\RH_App\venv\Lib\site-packages\django\db\backends\utils.py", line 122, in execute
    return super().execute(sql, params)
           ~~~~~~~~~~~~~~~^^^^^^^^^^^^^
  File "C:\Users\A\Desktop\Digitall Skills\RH_App\venv\Lib\site-packages\django\db\backends\utils.py", line 79, in execute
    return self._execute_with_wrappers(
           ~~~~~~~~~~~~~~~~~~~~~~~~~~~^
        sql, params, many=False, executor=self._execute
        ^^^^^^^^^^^^^^^^^^^^^^^^^^^^^^^^^^^^^^^^^^^^^^^
    )
    ^
  File "C:\Users\A\Desktop\Digitall Skills\RH_App\venv\Lib\site-packages\django\db\backends\utils.py", line 92, in _execute_with_wrappers
    return executor(sql, params, many, context)
  File "C:\Users\A\Desktop\Digitall Skills\RH_App\venv\Lib\site-packages\django\db\backends\utils.py", line 100, in _execute
    with self.db.wrap_database_errors:
         ^^^^^^^^^^^^^^^^^^^^^^^^^^^^
  File "C:\Users\A\Desktop\Digitall Skills\RH_App\venv\Lib\site-packages\django\db\utils.py", line 91, in __exit__
    raise dj_exc_value.with_traceback(traceback) from exc_value
  File "C:\Users\A\Desktop\Digitall Skills\RH_App\venv\Lib\site-packages\django\db\backends\utils.py", line 105, in _execute
    return self.cursor.execute(sql, params)
           ~~~~~~~~~~~~~~~~~~~^^^^^^^^^^^^^
  File "C:\Users\A\Desktop\Digitall Skills\RH_App\venv\Lib\site-packages\django\db\backends\sqlite3\base.py", line 328, in execute
    return super().execute(query, params)
           ~~~~~~~~~~~~~~~^^^^^^^^^^^^^^^
django.db.utils.OperationalError: no such table: users
ERROR 2025-08-23 23:17:31,721 basehttp 13140 24408 "POST /api/auth/login/ HTTP/1.1" 500 229572
ERROR 2025-08-23 23:21:03,946 log 13140 3712 Internal Server Error: /api/auth/login/
Traceback (most recent call last):
  File "C:\Users\A\Desktop\Digitall Skills\RH_App\venv\Lib\site-packages\django\db\backends\utils.py", line 105, in _execute
    return self.cursor.execute(sql, params)
           ~~~~~~~~~~~~~~~~~~~^^^^^^^^^^^^^
  File "C:\Users\A\Desktop\Digitall Skills\RH_App\venv\Lib\site-packages\django\db\backends\sqlite3\base.py", line 328, in execute
    return super().execute(query, params)
           ~~~~~~~~~~~~~~~^^^^^^^^^^^^^^^
sqlite3.OperationalError: no such table: users

The above exception was the direct cause of the following exception:

Traceback (most recent call last):
  File "C:\Users\A\Desktop\Digitall Skills\RH_App\venv\Lib\site-packages\django\core\handlers\exception.py", line 55, in inner
    response = get_response(request)
  File "C:\Users\A\Desktop\Digitall Skills\RH_App\venv\Lib\site-packages\django\core\handlers\base.py", line 197, in _get_response
    response = wrapped_callback(request, *callback_args, **callback_kwargs)
  File "C:\Users\A\Desktop\Digitall Skills\RH_App\venv\Lib\site-packages\django\views\decorators\csrf.py", line 65, in _view_wrapper
    return view_func(request, *args, **kwargs)
  File "C:\Users\A\Desktop\Digitall Skills\RH_App\venv\Lib\site-packages\django\views\generic\base.py", line 104, in view
    return self.dispatch(request, *args, **kwargs)
           ~~~~~~~~~~~~~^^^^^^^^^^^^^^^^^^^^^^^^^^
  File "C:\Users\A\Desktop\Digitall Skills\RH_App\venv\Lib\site-packages\rest_framework\views.py", line 509, in dispatch
    response = self.handle_exception(exc)
  File "C:\Users\A\Desktop\Digitall Skills\RH_App\venv\Lib\site-packages\rest_framework\views.py", line 469, in handle_exception
    self.raise_uncaught_exception(exc)
    ~~~~~~~~~~~~~~~~~~~~~~~~~~~~~^^^^^
  File "C:\Users\A\Desktop\Digitall Skills\RH_App\venv\Lib\site-packages\rest_framework\views.py", line 480, in raise_uncaught_exception
    raise exc
  File "C:\Users\A\Desktop\Digitall Skills\RH_App\venv\Lib\site-packages\rest_framework\views.py", line 506, in dispatch
    response = handler(request, *args, **kwargs)
  File "C:\Users\A\Desktop\Digitall Skills\RH_App\venv\Lib\site-packages\rest_framework_simplejwt\views.py", line 46, in post
    serializer.is_valid(raise_exception=True)
    ~~~~~~~~~~~~~~~~~~~^^^^^^^^^^^^^^^^^^^^^^
  File "C:\Users\A\Desktop\Digitall Skills\RH_App\venv\Lib\site-packages\rest_framework\serializers.py", line 227, in is_valid
    self._validated_data = self.run_validation(self.initial_data)
                           ~~~~~~~~~~~~~~~~~~~^^^^^^^^^^^^^^^^^^^
  File "C:\Users\A\Desktop\Digitall Skills\RH_App\venv\Lib\site-packages\rest_framework\serializers.py", line 429, in run_validation
    value = self.validate(value)
  File "C:\Users\A\Desktop\Digitall Skills\RH_App\venv\Lib\site-packages\rest_framework_simplejwt\serializers.py", line 73, in validate
    data = super().validate(attrs)
  File "C:\Users\A\Desktop\Digitall Skills\RH_App\venv\Lib\site-packages\rest_framework_simplejwt\serializers.py", line 54, in validate
    self.user = authenticate(**authenticate_kwargs)
                ~~~~~~~~~~~~^^^^^^^^^^^^^^^^^^^^^^^
  File "C:\Users\A\Desktop\Digitall Skills\RH_App\venv\Lib\site-packages\django\views\decorators\debug.py", line 73, in sensitive_variables_wrapper
    return func(*func_args, **func_kwargs)
  File "C:\Users\A\Desktop\Digitall Skills\RH_App\venv\Lib\site-packages\django\contrib\auth\__init__.py", line 79, in authenticate
    user = backend.authenticate(request, **credentials)
  File "C:\Users\A\Desktop\Digitall Skills\RH_App\venv\Lib\site-packages\django\contrib\auth\backends.py", line 42, in authenticate
    user = UserModel._default_manager.get_by_natural_key(username)
  File "C:\Users\A\Desktop\Digitall Skills\RH_App\venv\Lib\site-packages\django\contrib\auth\base_user.py", line 55, in get_by_natural_key
    return self.get(**{self.model.USERNAME_FIELD: username})
           ~~~~~~~~^^^^^^^^^^^^^^^^^^^^^^^^^^^^^^^^^^^^^^^^^
  File "C:\Users\A\Desktop\Digitall Skills\RH_App\venv\Lib\site-packages\django\db\models\manager.py", line 87, in manager_method
    return getattr(self.get_queryset(), name)(*args, **kwargs)
           ~~~~~~~~~~~~~~~~~~~~~~~~~~~~~~~~~~^^^^^^^^^^^^^^^^^
  File "C:\Users\A\Desktop\Digitall Skills\RH_App\venv\Lib\site-packages\django\db\models\query.py", line 643, in get
    num = len(clone)
  File "C:\Users\A\Desktop\Digitall Skills\RH_App\venv\Lib\site-packages\django\db\models\query.py", line 380, in __len__
    self._fetch_all()
    ~~~~~~~~~~~~~~~^^
  File "C:\Users\A\Desktop\Digitall Skills\RH_App\venv\Lib\site-packages\django\db\models\query.py", line 1926, in _fetch_all
    self._result_cache = list(self._iterable_class(self))
                         ~~~~^^^^^^^^^^^^^^^^^^^^^^^^^^^^
  File "C:\Users\A\Desktop\Digitall Skills\RH_App\venv\Lib\site-packages\django\db\models\query.py", line 91, in __iter__
    results = compiler.execute_sql(
        chunked_fetch=self.chunked_fetch, chunk_size=self.chunk_size
    )
  File "C:\Users\A\Desktop\Digitall Skills\RH_App\venv\Lib\site-packages\django\db\models\sql\compiler.py", line 1562, in execute_sql
    cursor.execute(sql, params)
    ~~~~~~~~~~~~~~^^^^^^^^^^^^^
  File "C:\Users\A\Desktop\Digitall Skills\RH_App\venv\Lib\site-packages\django\db\backends\utils.py", line 122, in execute
    return super().execute(sql, params)
           ~~~~~~~~~~~~~~~^^^^^^^^^^^^^
  File "C:\Users\A\Desktop\Digitall Skills\RH_App\venv\Lib\site-packages\django\db\backends\utils.py", line 79, in execute
    return self._execute_with_wrappers(
           ~~~~~~~~~~~~~~~~~~~~~~~~~~~^
        sql, params, many=False, executor=self._execute
        ^^^^^^^^^^^^^^^^^^^^^^^^^^^^^^^^^^^^^^^^^^^^^^^
    )
    ^
  File "C:\Users\A\Desktop\Digitall Skills\RH_App\venv\Lib\site-packages\django\db\backends\utils.py", line 92, in _execute_with_wrappers
    return executor(sql, params, many, context)
  File "C:\Users\A\Desktop\Digitall Skills\RH_App\venv\Lib\site-packages\django\db\backends\utils.py", line 100, in _execute
    with self.db.wrap_database_errors:
         ^^^^^^^^^^^^^^^^^^^^^^^^^^^^
  File "C:\Users\A\Desktop\Digitall Skills\RH_App\venv\Lib\site-packages\django\db\utils.py", line 91, in __exit__
    raise dj_exc_value.with_traceback(traceback) from exc_value
  File "C:\Users\A\Desktop\Digitall Skills\RH_App\venv\Lib\site-packages\django\db\backends\utils.py", line 105, in _execute
    return self.cursor.execute(sql, params)
           ~~~~~~~~~~~~~~~~~~~^^^^^^^^^^^^^
  File "C:\Users\A\Desktop\Digitall Skills\RH_App\venv\Lib\site-packages\django\db\backends\sqlite3\base.py", line 328, in execute
    return super().execute(query, params)
           ~~~~~~~~~~~~~~~^^^^^^^^^^^^^^^
django.db.utils.OperationalError: no such table: users
ERROR 2025-08-23 23:21:03,969 basehttp 13140 3712 "POST /api/auth/login/ HTTP/1.1" 500 229572
ERROR 2025-08-23 23:21:05,031 log 13140 23512 Internal Server Error: /api/auth/login/
Traceback (most recent call last):
  File "C:\Users\A\Desktop\Digitall Skills\RH_App\venv\Lib\site-packages\django\db\backends\utils.py", line 105, in _execute
    return self.cursor.execute(sql, params)
           ~~~~~~~~~~~~~~~~~~~^^^^^^^^^^^^^
  File "C:\Users\A\Desktop\Digitall Skills\RH_App\venv\Lib\site-packages\django\db\backends\sqlite3\base.py", line 328, in execute
    return super().execute(query, params)
           ~~~~~~~~~~~~~~~^^^^^^^^^^^^^^^
sqlite3.OperationalError: no such table: users

The above exception was the direct cause of the following exception:

Traceback (most recent call last):
  File "C:\Users\A\Desktop\Digitall Skills\RH_App\venv\Lib\site-packages\django\core\handlers\exception.py", line 55, in inner
    response = get_response(request)
  File "C:\Users\A\Desktop\Digitall Skills\RH_App\venv\Lib\site-packages\django\core\handlers\base.py", line 197, in _get_response
    response = wrapped_callback(request, *callback_args, **callback_kwargs)
  File "C:\Users\A\Desktop\Digitall Skills\RH_App\venv\Lib\site-packages\django\views\decorators\csrf.py", line 65, in _view_wrapper
    return view_func(request, *args, **kwargs)
  File "C:\Users\A\Desktop\Digitall Skills\RH_App\venv\Lib\site-packages\django\views\generic\base.py", line 104, in view
    return self.dispatch(request, *args, **kwargs)
           ~~~~~~~~~~~~~^^^^^^^^^^^^^^^^^^^^^^^^^^
  File "C:\Users\A\Desktop\Digitall Skills\RH_App\venv\Lib\site-packages\rest_framework\views.py", line 509, in dispatch
    response = self.handle_exception(exc)
  File "C:\Users\A\Desktop\Digitall Skills\RH_App\venv\Lib\site-packages\rest_framework\views.py", line 469, in handle_exception
    self.raise_uncaught_exception(exc)
    ~~~~~~~~~~~~~~~~~~~~~~~~~~~~~^^^^^
  File "C:\Users\A\Desktop\Digitall Skills\RH_App\venv\Lib\site-packages\rest_framework\views.py", line 480, in raise_uncaught_exception
    raise exc
  File "C:\Users\A\Desktop\Digitall Skills\RH_App\venv\Lib\site-packages\rest_framework\views.py", line 506, in dispatch
    response = handler(request, *args, **kwargs)
  File "C:\Users\A\Desktop\Digitall Skills\RH_App\venv\Lib\site-packages\rest_framework_simplejwt\views.py", line 46, in post
    serializer.is_valid(raise_exception=True)
    ~~~~~~~~~~~~~~~~~~~^^^^^^^^^^^^^^^^^^^^^^
  File "C:\Users\A\Desktop\Digitall Skills\RH_App\venv\Lib\site-packages\rest_framework\serializers.py", line 227, in is_valid
    self._validated_data = self.run_validation(self.initial_data)
                           ~~~~~~~~~~~~~~~~~~~^^^^^^^^^^^^^^^^^^^
  File "C:\Users\A\Desktop\Digitall Skills\RH_App\venv\Lib\site-packages\rest_framework\serializers.py", line 429, in run_validation
    value = self.validate(value)
  File "C:\Users\A\Desktop\Digitall Skills\RH_App\venv\Lib\site-packages\rest_framework_simplejwt\serializers.py", line 73, in validate
    data = super().validate(attrs)
  File "C:\Users\A\Desktop\Digitall Skills\RH_App\venv\Lib\site-packages\rest_framework_simplejwt\serializers.py", line 54, in validate
    self.user = authenticate(**authenticate_kwargs)
                ~~~~~~~~~~~~^^^^^^^^^^^^^^^^^^^^^^^
  File "C:\Users\A\Desktop\Digitall Skills\RH_App\venv\Lib\site-packages\django\views\decorators\debug.py", line 73, in sensitive_variables_wrapper
    return func(*func_args, **func_kwargs)
  File "C:\Users\A\Desktop\Digitall Skills\RH_App\venv\Lib\site-packages\django\contrib\auth\__init__.py", line 79, in authenticate
    user = backend.authenticate(request, **credentials)
  File "C:\Users\A\Desktop\Digitall Skills\RH_App\venv\Lib\site-packages\django\contrib\auth\backends.py", line 42, in authenticate
    user = UserModel._default_manager.get_by_natural_key(username)
  File "C:\Users\A\Desktop\Digitall Skills\RH_App\venv\Lib\site-packages\django\contrib\auth\base_user.py", line 55, in get_by_natural_key
    return self.get(**{self.model.USERNAME_FIELD: username})
           ~~~~~~~~^^^^^^^^^^^^^^^^^^^^^^^^^^^^^^^^^^^^^^^^^
  File "C:\Users\A\Desktop\Digitall Skills\RH_App\venv\Lib\site-packages\django\db\models\manager.py", line 87, in manager_method
    return getattr(self.get_queryset(), name)(*args, **kwargs)
           ~~~~~~~~~~~~~~~~~~~~~~~~~~~~~~~~~~^^^^^^^^^^^^^^^^^
  File "C:\Users\A\Desktop\Digitall Skills\RH_App\venv\Lib\site-packages\django\db\models\query.py", line 643, in get
    num = len(clone)
  File "C:\Users\A\Desktop\Digitall Skills\RH_App\venv\Lib\site-packages\django\db\models\query.py", line 380, in __len__
    self._fetch_all()
    ~~~~~~~~~~~~~~~^^
  File "C:\Users\A\Desktop\Digitall Skills\RH_App\venv\Lib\site-packages\django\db\models\query.py", line 1926, in _fetch_all
    self._result_cache = list(self._iterable_class(self))
                         ~~~~^^^^^^^^^^^^^^^^^^^^^^^^^^^^
  File "C:\Users\A\Desktop\Digitall Skills\RH_App\venv\Lib\site-packages\django\db\models\query.py", line 91, in __iter__
    results = compiler.execute_sql(
        chunked_fetch=self.chunked_fetch, chunk_size=self.chunk_size
    )
  File "C:\Users\A\Desktop\Digitall Skills\RH_App\venv\Lib\site-packages\django\db\models\sql\compiler.py", line 1562, in execute_sql
    cursor.execute(sql, params)
    ~~~~~~~~~~~~~~^^^^^^^^^^^^^
  File "C:\Users\A\Desktop\Digitall Skills\RH_App\venv\Lib\site-packages\django\db\backends\utils.py", line 122, in execute
    return super().execute(sql, params)
           ~~~~~~~~~~~~~~~^^^^^^^^^^^^^
  File "C:\Users\A\Desktop\Digitall Skills\RH_App\venv\Lib\site-packages\django\db\backends\utils.py", line 79, in execute
    return self._execute_with_wrappers(
           ~~~~~~~~~~~~~~~~~~~~~~~~~~~^
        sql, params, many=False, executor=self._execute
        ^^^^^^^^^^^^^^^^^^^^^^^^^^^^^^^^^^^^^^^^^^^^^^^
    )
    ^
  File "C:\Users\A\Desktop\Digitall Skills\RH_App\venv\Lib\site-packages\django\db\backends\utils.py", line 92, in _execute_with_wrappers
    return executor(sql, params, many, context)
  File "C:\Users\A\Desktop\Digitall Skills\RH_App\venv\Lib\site-packages\django\db\backends\utils.py", line 100, in _execute
    with self.db.wrap_database_errors:
         ^^^^^^^^^^^^^^^^^^^^^^^^^^^^
  File "C:\Users\A\Desktop\Digitall Skills\RH_App\venv\Lib\site-packages\django\db\utils.py", line 91, in __exit__
    raise dj_exc_value.with_traceback(traceback) from exc_value
  File "C:\Users\A\Desktop\Digitall Skills\RH_App\venv\Lib\site-packages\django\db\backends\utils.py", line 105, in _execute
    return self.cursor.execute(sql, params)
           ~~~~~~~~~~~~~~~~~~~^^^^^^^^^^^^^
  File "C:\Users\A\Desktop\Digitall Skills\RH_App\venv\Lib\site-packages\django\db\backends\sqlite3\base.py", line 328, in execute
    return super().execute(query, params)
           ~~~~~~~~~~~~~~~^^^^^^^^^^^^^^^
django.db.utils.OperationalError: no such table: users
ERROR 2025-08-23 23:21:05,045 basehttp 13140 23512 "POST /api/auth/login/ HTTP/1.1" 500 229572
ERROR 2025-08-23 23:21:17,772 log 13140 3888 Internal Server Error: /api/auth/login/
Traceback (most recent call last):
  File "C:\Users\A\Desktop\Digitall Skills\RH_App\venv\Lib\site-packages\django\db\backends\utils.py", line 105, in _execute
    return self.cursor.execute(sql, params)
           ~~~~~~~~~~~~~~~~~~~^^^^^^^^^^^^^
  File "C:\Users\A\Desktop\Digitall Skills\RH_App\venv\Lib\site-packages\django\db\backends\sqlite3\base.py", line 328, in execute
    return super().execute(query, params)
           ~~~~~~~~~~~~~~~^^^^^^^^^^^^^^^
sqlite3.OperationalError: no such table: users

The above exception was the direct cause of the following exception:

Traceback (most recent call last):
  File "C:\Users\A\Desktop\Digitall Skills\RH_App\venv\Lib\site-packages\django\core\handlers\exception.py", line 55, in inner
    response = get_response(request)
  File "C:\Users\A\Desktop\Digitall Skills\RH_App\venv\Lib\site-packages\django\core\handlers\base.py", line 197, in _get_response
    response = wrapped_callback(request, *callback_args, **callback_kwargs)
  File "C:\Users\A\Desktop\Digitall Skills\RH_App\venv\Lib\site-packages\django\views\decorators\csrf.py", line 65, in _view_wrapper
    return view_func(request, *args, **kwargs)
  File "C:\Users\A\Desktop\Digitall Skills\RH_App\venv\Lib\site-packages\django\views\generic\base.py", line 104, in view
    return self.dispatch(request, *args, **kwargs)
           ~~~~~~~~~~~~~^^^^^^^^^^^^^^^^^^^^^^^^^^
  File "C:\Users\A\Desktop\Digitall Skills\RH_App\venv\Lib\site-packages\rest_framework\views.py", line 509, in dispatch
    response = self.handle_exception(exc)
  File "C:\Users\A\Desktop\Digitall Skills\RH_App\venv\Lib\site-packages\rest_framework\views.py", line 469, in handle_exception
    self.raise_uncaught_exception(exc)
    ~~~~~~~~~~~~~~~~~~~~~~~~~~~~~^^^^^
  File "C:\Users\A\Desktop\Digitall Skills\RH_App\venv\Lib\site-packages\rest_framework\views.py", line 480, in raise_uncaught_exception
    raise exc
  File "C:\Users\A\Desktop\Digitall Skills\RH_App\venv\Lib\site-packages\rest_framework\views.py", line 506, in dispatch
    response = handler(request, *args, **kwargs)
  File "C:\Users\A\Desktop\Digitall Skills\RH_App\venv\Lib\site-packages\rest_framework_simplejwt\views.py", line 46, in post
    serializer.is_valid(raise_exception=True)
    ~~~~~~~~~~~~~~~~~~~^^^^^^^^^^^^^^^^^^^^^^
  File "C:\Users\A\Desktop\Digitall Skills\RH_App\venv\Lib\site-packages\rest_framework\serializers.py", line 227, in is_valid
    self._validated_data = self.run_validation(self.initial_data)
                           ~~~~~~~~~~~~~~~~~~~^^^^^^^^^^^^^^^^^^^
  File "C:\Users\A\Desktop\Digitall Skills\RH_App\venv\Lib\site-packages\rest_framework\serializers.py", line 429, in run_validation
    value = self.validate(value)
  File "C:\Users\A\Desktop\Digitall Skills\RH_App\venv\Lib\site-packages\rest_framework_simplejwt\serializers.py", line 73, in validate
    data = super().validate(attrs)
  File "C:\Users\A\Desktop\Digitall Skills\RH_App\venv\Lib\site-packages\rest_framework_simplejwt\serializers.py", line 54, in validate
    self.user = authenticate(**authenticate_kwargs)
                ~~~~~~~~~~~~^^^^^^^^^^^^^^^^^^^^^^^
  File "C:\Users\A\Desktop\Digitall Skills\RH_App\venv\Lib\site-packages\django\views\decorators\debug.py", line 73, in sensitive_variables_wrapper
    return func(*func_args, **func_kwargs)
  File "C:\Users\A\Desktop\Digitall Skills\RH_App\venv\Lib\site-packages\django\contrib\auth\__init__.py", line 79, in authenticate
    user = backend.authenticate(request, **credentials)
  File "C:\Users\A\Desktop\Digitall Skills\RH_App\venv\Lib\site-packages\django\contrib\auth\backends.py", line 42, in authenticate
    user = UserModel._default_manager.get_by_natural_key(username)
  File "C:\Users\A\Desktop\Digitall Skills\RH_App\venv\Lib\site-packages\django\contrib\auth\base_user.py", line 55, in get_by_natural_key
    return self.get(**{self.model.USERNAME_FIELD: username})
           ~~~~~~~~^^^^^^^^^^^^^^^^^^^^^^^^^^^^^^^^^^^^^^^^^
  File "C:\Users\A\Desktop\Digitall Skills\RH_App\venv\Lib\site-packages\django\db\models\manager.py", line 87, in manager_method
    return getattr(self.get_queryset(), name)(*args, **kwargs)
           ~~~~~~~~~~~~~~~~~~~~~~~~~~~~~~~~~~^^^^^^^^^^^^^^^^^
  File "C:\Users\A\Desktop\Digitall Skills\RH_App\venv\Lib\site-packages\django\db\models\query.py", line 643, in get
    num = len(clone)
  File "C:\Users\A\Desktop\Digitall Skills\RH_App\venv\Lib\site-packages\django\db\models\query.py", line 380, in __len__
    self._fetch_all()
    ~~~~~~~~~~~~~~~^^
  File "C:\Users\A\Desktop\Digitall Skills\RH_App\venv\Lib\site-packages\django\db\models\query.py", line 1926, in _fetch_all
    self._result_cache = list(self._iterable_class(self))
                         ~~~~^^^^^^^^^^^^^^^^^^^^^^^^^^^^
  File "C:\Users\A\Desktop\Digitall Skills\RH_App\venv\Lib\site-packages\django\db\models\query.py", line 91, in __iter__
    results = compiler.execute_sql(
        chunked_fetch=self.chunked_fetch, chunk_size=self.chunk_size
    )
  File "C:\Users\A\Desktop\Digitall Skills\RH_App\venv\Lib\site-packages\django\db\models\sql\compiler.py", line 1562, in execute_sql
    cursor.execute(sql, params)
    ~~~~~~~~~~~~~~^^^^^^^^^^^^^
  File "C:\Users\A\Desktop\Digitall Skills\RH_App\venv\Lib\site-packages\django\db\backends\utils.py", line 122, in execute
    return super().execute(sql, params)
           ~~~~~~~~~~~~~~~^^^^^^^^^^^^^
  File "C:\Users\A\Desktop\Digitall Skills\RH_App\venv\Lib\site-packages\django\db\backends\utils.py", line 79, in execute
    return self._execute_with_wrappers(
           ~~~~~~~~~~~~~~~~~~~~~~~~~~~^
        sql, params, many=False, executor=self._execute
        ^^^^^^^^^^^^^^^^^^^^^^^^^^^^^^^^^^^^^^^^^^^^^^^
    )
    ^
  File "C:\Users\A\Desktop\Digitall Skills\RH_App\venv\Lib\site-packages\django\db\backends\utils.py", line 92, in _execute_with_wrappers
    return executor(sql, params, many, context)
  File "C:\Users\A\Desktop\Digitall Skills\RH_App\venv\Lib\site-packages\django\db\backends\utils.py", line 100, in _execute
    with self.db.wrap_database_errors:
         ^^^^^^^^^^^^^^^^^^^^^^^^^^^^
  File "C:\Users\A\Desktop\Digitall Skills\RH_App\venv\Lib\site-packages\django\db\utils.py", line 91, in __exit__
    raise dj_exc_value.with_traceback(traceback) from exc_value
  File "C:\Users\A\Desktop\Digitall Skills\RH_App\venv\Lib\site-packages\django\db\backends\utils.py", line 105, in _execute
    return self.cursor.execute(sql, params)
           ~~~~~~~~~~~~~~~~~~~^^^^^^^^^^^^^
  File "C:\Users\A\Desktop\Digitall Skills\RH_App\venv\Lib\site-packages\django\db\backends\sqlite3\base.py", line 328, in execute
    return super().execute(query, params)
           ~~~~~~~~~~~~~~~^^^^^^^^^^^^^^^
django.db.utils.OperationalError: no such table: users
ERROR 2025-08-23 23:21:17,789 basehttp 13140 3888 "POST /api/auth/login/ HTTP/1.1" 500 229572
ERROR 2025-08-23 23:21:22,612 log 13140 3888 Internal Server Error: /api/auth/login/
Traceback (most recent call last):
  File "C:\Users\A\Desktop\Digitall Skills\RH_App\venv\Lib\site-packages\django\db\backends\utils.py", line 105, in _execute
    return self.cursor.execute(sql, params)
           ~~~~~~~~~~~~~~~~~~~^^^^^^^^^^^^^
  File "C:\Users\A\Desktop\Digitall Skills\RH_App\venv\Lib\site-packages\django\db\backends\sqlite3\base.py", line 328, in execute
    return super().execute(query, params)
           ~~~~~~~~~~~~~~~^^^^^^^^^^^^^^^
sqlite3.OperationalError: no such table: users

The above exception was the direct cause of the following exception:

Traceback (most recent call last):
  File "C:\Users\A\Desktop\Digitall Skills\RH_App\venv\Lib\site-packages\django\core\handlers\exception.py", line 55, in inner
    response = get_response(request)
  File "C:\Users\A\Desktop\Digitall Skills\RH_App\venv\Lib\site-packages\django\core\handlers\base.py", line 197, in _get_response
    response = wrapped_callback(request, *callback_args, **callback_kwargs)
  File "C:\Users\A\Desktop\Digitall Skills\RH_App\venv\Lib\site-packages\django\views\decorators\csrf.py", line 65, in _view_wrapper
    return view_func(request, *args, **kwargs)
  File "C:\Users\A\Desktop\Digitall Skills\RH_App\venv\Lib\site-packages\django\views\generic\base.py", line 104, in view
    return self.dispatch(request, *args, **kwargs)
           ~~~~~~~~~~~~~^^^^^^^^^^^^^^^^^^^^^^^^^^
  File "C:\Users\A\Desktop\Digitall Skills\RH_App\venv\Lib\site-packages\rest_framework\views.py", line 509, in dispatch
    response = self.handle_exception(exc)
  File "C:\Users\A\Desktop\Digitall Skills\RH_App\venv\Lib\site-packages\rest_framework\views.py", line 469, in handle_exception
    self.raise_uncaught_exception(exc)
    ~~~~~~~~~~~~~~~~~~~~~~~~~~~~~^^^^^
  File "C:\Users\A\Desktop\Digitall Skills\RH_App\venv\Lib\site-packages\rest_framework\views.py", line 480, in raise_uncaught_exception
    raise exc
  File "C:\Users\A\Desktop\Digitall Skills\RH_App\venv\Lib\site-packages\rest_framework\views.py", line 506, in dispatch
    response = handler(request, *args, **kwargs)
  File "C:\Users\A\Desktop\Digitall Skills\RH_App\venv\Lib\site-packages\rest_framework_simplejwt\views.py", line 46, in post
    serializer.is_valid(raise_exception=True)
    ~~~~~~~~~~~~~~~~~~~^^^^^^^^^^^^^^^^^^^^^^
  File "C:\Users\A\Desktop\Digitall Skills\RH_App\venv\Lib\site-packages\rest_framework\serializers.py", line 227, in is_valid
    self._validated_data = self.run_validation(self.initial_data)
                           ~~~~~~~~~~~~~~~~~~~^^^^^^^^^^^^^^^^^^^
  File "C:\Users\A\Desktop\Digitall Skills\RH_App\venv\Lib\site-packages\rest_framework\serializers.py", line 429, in run_validation
    value = self.validate(value)
  File "C:\Users\A\Desktop\Digitall Skills\RH_App\venv\Lib\site-packages\rest_framework_simplejwt\serializers.py", line 73, in validate
    data = super().validate(attrs)
  File "C:\Users\A\Desktop\Digitall Skills\RH_App\venv\Lib\site-packages\rest_framework_simplejwt\serializers.py", line 54, in validate
    self.user = authenticate(**authenticate_kwargs)
                ~~~~~~~~~~~~^^^^^^^^^^^^^^^^^^^^^^^
  File "C:\Users\A\Desktop\Digitall Skills\RH_App\venv\Lib\site-packages\django\views\decorators\debug.py", line 73, in sensitive_variables_wrapper
    return func(*func_args, **func_kwargs)
  File "C:\Users\A\Desktop\Digitall Skills\RH_App\venv\Lib\site-packages\django\contrib\auth\__init__.py", line 79, in authenticate
    user = backend.authenticate(request, **credentials)
  File "C:\Users\A\Desktop\Digitall Skills\RH_App\venv\Lib\site-packages\django\contrib\auth\backends.py", line 42, in authenticate
    user = UserModel._default_manager.get_by_natural_key(username)
  File "C:\Users\A\Desktop\Digitall Skills\RH_App\venv\Lib\site-packages\django\contrib\auth\base_user.py", line 55, in get_by_natural_key
    return self.get(**{self.model.USERNAME_FIELD: username})
           ~~~~~~~~^^^^^^^^^^^^^^^^^^^^^^^^^^^^^^^^^^^^^^^^^
  File "C:\Users\A\Desktop\Digitall Skills\RH_App\venv\Lib\site-packages\django\db\models\manager.py", line 87, in manager_method
    return getattr(self.get_queryset(), name)(*args, **kwargs)
           ~~~~~~~~~~~~~~~~~~~~~~~~~~~~~~~~~~^^^^^^^^^^^^^^^^^
  File "C:\Users\A\Desktop\Digitall Skills\RH_App\venv\Lib\site-packages\django\db\models\query.py", line 643, in get
    num = len(clone)
  File "C:\Users\A\Desktop\Digitall Skills\RH_App\venv\Lib\site-packages\django\db\models\query.py", line 380, in __len__
    self._fetch_all()
    ~~~~~~~~~~~~~~~^^
  File "C:\Users\A\Desktop\Digitall Skills\RH_App\venv\Lib\site-packages\django\db\models\query.py", line 1926, in _fetch_all
    self._result_cache = list(self._iterable_class(self))
                         ~~~~^^^^^^^^^^^^^^^^^^^^^^^^^^^^
  File "C:\Users\A\Desktop\Digitall Skills\RH_App\venv\Lib\site-packages\django\db\models\query.py", line 91, in __iter__
    results = compiler.execute_sql(
        chunked_fetch=self.chunked_fetch, chunk_size=self.chunk_size
    )
  File "C:\Users\A\Desktop\Digitall Skills\RH_App\venv\Lib\site-packages\django\db\models\sql\compiler.py", line 1562, in execute_sql
    cursor.execute(sql, params)
    ~~~~~~~~~~~~~~^^^^^^^^^^^^^
  File "C:\Users\A\Desktop\Digitall Skills\RH_App\venv\Lib\site-packages\django\db\backends\utils.py", line 122, in execute
    return super().execute(sql, params)
           ~~~~~~~~~~~~~~~^^^^^^^^^^^^^
  File "C:\Users\A\Desktop\Digitall Skills\RH_App\venv\Lib\site-packages\django\db\backends\utils.py", line 79, in execute
    return self._execute_with_wrappers(
           ~~~~~~~~~~~~~~~~~~~~~~~~~~~^
        sql, params, many=False, executor=self._execute
        ^^^^^^^^^^^^^^^^^^^^^^^^^^^^^^^^^^^^^^^^^^^^^^^
    )
    ^
  File "C:\Users\A\Desktop\Digitall Skills\RH_App\venv\Lib\site-packages\django\db\backends\utils.py", line 92, in _execute_with_wrappers
    return executor(sql, params, many, context)
  File "C:\Users\A\Desktop\Digitall Skills\RH_App\venv\Lib\site-packages\django\db\backends\utils.py", line 100, in _execute
    with self.db.wrap_database_errors:
         ^^^^^^^^^^^^^^^^^^^^^^^^^^^^
  File "C:\Users\A\Desktop\Digitall Skills\RH_App\venv\Lib\site-packages\django\db\utils.py", line 91, in __exit__
    raise dj_exc_value.with_traceback(traceback) from exc_value
  File "C:\Users\A\Desktop\Digitall Skills\RH_App\venv\Lib\site-packages\django\db\backends\utils.py", line 105, in _execute
    return self.cursor.execute(sql, params)
           ~~~~~~~~~~~~~~~~~~~^^^^^^^^^^^^^
  File "C:\Users\A\Desktop\Digitall Skills\RH_App\venv\Lib\site-packages\django\db\backends\sqlite3\base.py", line 328, in execute
    return super().execute(query, params)
           ~~~~~~~~~~~~~~~^^^^^^^^^^^^^^^
django.db.utils.OperationalError: no such table: users
ERROR 2025-08-23 23:21:22,626 basehttp 13140 3888 "POST /api/auth/login/ HTTP/1.1" 500 229572
ERROR 2025-08-23 23:22:48,958 log 13140 1848 Internal Server Error: /api/auth/login/
Traceback (most recent call last):
  File "C:\Users\A\Desktop\Digitall Skills\RH_App\venv\Lib\site-packages\django\db\backends\utils.py", line 105, in _execute
    return self.cursor.execute(sql, params)
           ~~~~~~~~~~~~~~~~~~~^^^^^^^^^^^^^
  File "C:\Users\A\Desktop\Digitall Skills\RH_App\venv\Lib\site-packages\django\db\backends\sqlite3\base.py", line 328, in execute
    return super().execute(query, params)
           ~~~~~~~~~~~~~~~^^^^^^^^^^^^^^^
sqlite3.OperationalError: no such table: users

The above exception was the direct cause of the following exception:

Traceback (most recent call last):
  File "C:\Users\A\Desktop\Digitall Skills\RH_App\venv\Lib\site-packages\django\core\handlers\exception.py", line 55, in inner
    response = get_response(request)
  File "C:\Users\A\Desktop\Digitall Skills\RH_App\venv\Lib\site-packages\django\core\handlers\base.py", line 197, in _get_response
    response = wrapped_callback(request, *callback_args, **callback_kwargs)
  File "C:\Users\A\Desktop\Digitall Skills\RH_App\venv\Lib\site-packages\django\views\decorators\csrf.py", line 65, in _view_wrapper
    return view_func(request, *args, **kwargs)
  File "C:\Users\A\Desktop\Digitall Skills\RH_App\venv\Lib\site-packages\django\views\generic\base.py", line 104, in view
    return self.dispatch(request, *args, **kwargs)
           ~~~~~~~~~~~~~^^^^^^^^^^^^^^^^^^^^^^^^^^
  File "C:\Users\A\Desktop\Digitall Skills\RH_App\venv\Lib\site-packages\rest_framework\views.py", line 509, in dispatch
    response = self.handle_exception(exc)
  File "C:\Users\A\Desktop\Digitall Skills\RH_App\venv\Lib\site-packages\rest_framework\views.py", line 469, in handle_exception
    self.raise_uncaught_exception(exc)
    ~~~~~~~~~~~~~~~~~~~~~~~~~~~~~^^^^^
  File "C:\Users\A\Desktop\Digitall Skills\RH_App\venv\Lib\site-packages\rest_framework\views.py", line 480, in raise_uncaught_exception
    raise exc
  File "C:\Users\A\Desktop\Digitall Skills\RH_App\venv\Lib\site-packages\rest_framework\views.py", line 506, in dispatch
    response = handler(request, *args, **kwargs)
  File "C:\Users\A\Desktop\Digitall Skills\RH_App\venv\Lib\site-packages\rest_framework_simplejwt\views.py", line 46, in post
    serializer.is_valid(raise_exception=True)
    ~~~~~~~~~~~~~~~~~~~^^^^^^^^^^^^^^^^^^^^^^
  File "C:\Users\A\Desktop\Digitall Skills\RH_App\venv\Lib\site-packages\rest_framework\serializers.py", line 227, in is_valid
    self._validated_data = self.run_validation(self.initial_data)
                           ~~~~~~~~~~~~~~~~~~~^^^^^^^^^^^^^^^^^^^
  File "C:\Users\A\Desktop\Digitall Skills\RH_App\venv\Lib\site-packages\rest_framework\serializers.py", line 429, in run_validation
    value = self.validate(value)
  File "C:\Users\A\Desktop\Digitall Skills\RH_App\venv\Lib\site-packages\rest_framework_simplejwt\serializers.py", line 73, in validate
    data = super().validate(attrs)
  File "C:\Users\A\Desktop\Digitall Skills\RH_App\venv\Lib\site-packages\rest_framework_simplejwt\serializers.py", line 54, in validate
    self.user = authenticate(**authenticate_kwargs)
                ~~~~~~~~~~~~^^^^^^^^^^^^^^^^^^^^^^^
  File "C:\Users\A\Desktop\Digitall Skills\RH_App\venv\Lib\site-packages\django\views\decorators\debug.py", line 73, in sensitive_variables_wrapper
    return func(*func_args, **func_kwargs)
  File "C:\Users\A\Desktop\Digitall Skills\RH_App\venv\Lib\site-packages\django\contrib\auth\__init__.py", line 79, in authenticate
    user = backend.authenticate(request, **credentials)
  File "C:\Users\A\Desktop\Digitall Skills\RH_App\venv\Lib\site-packages\django\contrib\auth\backends.py", line 42, in authenticate
    user = UserModel._default_manager.get_by_natural_key(username)
  File "C:\Users\A\Desktop\Digitall Skills\RH_App\venv\Lib\site-packages\django\contrib\auth\base_user.py", line 55, in get_by_natural_key
    return self.get(**{self.model.USERNAME_FIELD: username})
           ~~~~~~~~^^^^^^^^^^^^^^^^^^^^^^^^^^^^^^^^^^^^^^^^^
  File "C:\Users\A\Desktop\Digitall Skills\RH_App\venv\Lib\site-packages\django\db\models\manager.py", line 87, in manager_method
    return getattr(self.get_queryset(), name)(*args, **kwargs)
           ~~~~~~~~~~~~~~~~~~~~~~~~~~~~~~~~~~^^^^^^^^^^^^^^^^^
  File "C:\Users\A\Desktop\Digitall Skills\RH_App\venv\Lib\site-packages\django\db\models\query.py", line 643, in get
    num = len(clone)
  File "C:\Users\A\Desktop\Digitall Skills\RH_App\venv\Lib\site-packages\django\db\models\query.py", line 380, in __len__
    self._fetch_all()
    ~~~~~~~~~~~~~~~^^
  File "C:\Users\A\Desktop\Digitall Skills\RH_App\venv\Lib\site-packages\django\db\models\query.py", line 1926, in _fetch_all
    self._result_cache = list(self._iterable_class(self))
                         ~~~~^^^^^^^^^^^^^^^^^^^^^^^^^^^^
  File "C:\Users\A\Desktop\Digitall Skills\RH_App\venv\Lib\site-packages\django\db\models\query.py", line 91, in __iter__
    results = compiler.execute_sql(
        chunked_fetch=self.chunked_fetch, chunk_size=self.chunk_size
    )
  File "C:\Users\A\Desktop\Digitall Skills\RH_App\venv\Lib\site-packages\django\db\models\sql\compiler.py", line 1562, in execute_sql
    cursor.execute(sql, params)
    ~~~~~~~~~~~~~~^^^^^^^^^^^^^
  File "C:\Users\A\Desktop\Digitall Skills\RH_App\venv\Lib\site-packages\django\db\backends\utils.py", line 122, in execute
    return super().execute(sql, params)
           ~~~~~~~~~~~~~~~^^^^^^^^^^^^^
  File "C:\Users\A\Desktop\Digitall Skills\RH_App\venv\Lib\site-packages\django\db\backends\utils.py", line 79, in execute
    return self._execute_with_wrappers(
           ~~~~~~~~~~~~~~~~~~~~~~~~~~~^
        sql, params, many=False, executor=self._execute
        ^^^^^^^^^^^^^^^^^^^^^^^^^^^^^^^^^^^^^^^^^^^^^^^
    )
    ^
  File "C:\Users\A\Desktop\Digitall Skills\RH_App\venv\Lib\site-packages\django\db\backends\utils.py", line 92, in _execute_with_wrappers
    return executor(sql, params, many, context)
  File "C:\Users\A\Desktop\Digitall Skills\RH_App\venv\Lib\site-packages\django\db\backends\utils.py", line 100, in _execute
    with self.db.wrap_database_errors:
         ^^^^^^^^^^^^^^^^^^^^^^^^^^^^
  File "C:\Users\A\Desktop\Digitall Skills\RH_App\venv\Lib\site-packages\django\db\utils.py", line 91, in __exit__
    raise dj_exc_value.with_traceback(traceback) from exc_value
  File "C:\Users\A\Desktop\Digitall Skills\RH_App\venv\Lib\site-packages\django\db\backends\utils.py", line 105, in _execute
    return self.cursor.execute(sql, params)
           ~~~~~~~~~~~~~~~~~~~^^^^^^^^^^^^^
  File "C:\Users\A\Desktop\Digitall Skills\RH_App\venv\Lib\site-packages\django\db\backends\sqlite3\base.py", line 328, in execute
    return super().execute(query, params)
           ~~~~~~~~~~~~~~~^^^^^^^^^^^^^^^
django.db.utils.OperationalError: no such table: users
ERROR 2025-08-23 23:22:48,978 basehttp 13140 1848 "POST /api/auth/login/ HTTP/1.1" 500 229596
ERROR 2025-08-23 23:22:57,280 log 13140 19520 Internal Server Error: /api/auth/login/
Traceback (most recent call last):
  File "C:\Users\A\Desktop\Digitall Skills\RH_App\venv\Lib\site-packages\django\db\backends\utils.py", line 105, in _execute
    return self.cursor.execute(sql, params)
           ~~~~~~~~~~~~~~~~~~~^^^^^^^^^^^^^
  File "C:\Users\A\Desktop\Digitall Skills\RH_App\venv\Lib\site-packages\django\db\backends\sqlite3\base.py", line 328, in execute
    return super().execute(query, params)
           ~~~~~~~~~~~~~~~^^^^^^^^^^^^^^^
sqlite3.OperationalError: no such table: users

The above exception was the direct cause of the following exception:

Traceback (most recent call last):
  File "C:\Users\A\Desktop\Digitall Skills\RH_App\venv\Lib\site-packages\django\core\handlers\exception.py", line 55, in inner
    response = get_response(request)
  File "C:\Users\A\Desktop\Digitall Skills\RH_App\venv\Lib\site-packages\django\core\handlers\base.py", line 197, in _get_response
    response = wrapped_callback(request, *callback_args, **callback_kwargs)
  File "C:\Users\A\Desktop\Digitall Skills\RH_App\venv\Lib\site-packages\django\views\decorators\csrf.py", line 65, in _view_wrapper
    return view_func(request, *args, **kwargs)
  File "C:\Users\A\Desktop\Digitall Skills\RH_App\venv\Lib\site-packages\django\views\generic\base.py", line 104, in view
    return self.dispatch(request, *args, **kwargs)
           ~~~~~~~~~~~~~^^^^^^^^^^^^^^^^^^^^^^^^^^
  File "C:\Users\A\Desktop\Digitall Skills\RH_App\venv\Lib\site-packages\rest_framework\views.py", line 509, in dispatch
    response = self.handle_exception(exc)
  File "C:\Users\A\Desktop\Digitall Skills\RH_App\venv\Lib\site-packages\rest_framework\views.py", line 469, in handle_exception
    self.raise_uncaught_exception(exc)
    ~~~~~~~~~~~~~~~~~~~~~~~~~~~~~^^^^^
  File "C:\Users\A\Desktop\Digitall Skills\RH_App\venv\Lib\site-packages\rest_framework\views.py", line 480, in raise_uncaught_exception
    raise exc
  File "C:\Users\A\Desktop\Digitall Skills\RH_App\venv\Lib\site-packages\rest_framework\views.py", line 506, in dispatch
    response = handler(request, *args, **kwargs)
  File "C:\Users\A\Desktop\Digitall Skills\RH_App\venv\Lib\site-packages\rest_framework_simplejwt\views.py", line 46, in post
    serializer.is_valid(raise_exception=True)
    ~~~~~~~~~~~~~~~~~~~^^^^^^^^^^^^^^^^^^^^^^
  File "C:\Users\A\Desktop\Digitall Skills\RH_App\venv\Lib\site-packages\rest_framework\serializers.py", line 227, in is_valid
    self._validated_data = self.run_validation(self.initial_data)
                           ~~~~~~~~~~~~~~~~~~~^^^^^^^^^^^^^^^^^^^
  File "C:\Users\A\Desktop\Digitall Skills\RH_App\venv\Lib\site-packages\rest_framework\serializers.py", line 429, in run_validation
    value = self.validate(value)
  File "C:\Users\A\Desktop\Digitall Skills\RH_App\venv\Lib\site-packages\rest_framework_simplejwt\serializers.py", line 73, in validate
    data = super().validate(attrs)
  File "C:\Users\A\Desktop\Digitall Skills\RH_App\venv\Lib\site-packages\rest_framework_simplejwt\serializers.py", line 54, in validate
    self.user = authenticate(**authenticate_kwargs)
                ~~~~~~~~~~~~^^^^^^^^^^^^^^^^^^^^^^^
  File "C:\Users\A\Desktop\Digitall Skills\RH_App\venv\Lib\site-packages\django\views\decorators\debug.py", line 73, in sensitive_variables_wrapper
    return func(*func_args, **func_kwargs)
  File "C:\Users\A\Desktop\Digitall Skills\RH_App\venv\Lib\site-packages\django\contrib\auth\__init__.py", line 79, in authenticate
    user = backend.authenticate(request, **credentials)
  File "C:\Users\A\Desktop\Digitall Skills\RH_App\venv\Lib\site-packages\django\contrib\auth\backends.py", line 42, in authenticate
    user = UserModel._default_manager.get_by_natural_key(username)
  File "C:\Users\A\Desktop\Digitall Skills\RH_App\venv\Lib\site-packages\django\contrib\auth\base_user.py", line 55, in get_by_natural_key
    return self.get(**{self.model.USERNAME_FIELD: username})
           ~~~~~~~~^^^^^^^^^^^^^^^^^^^^^^^^^^^^^^^^^^^^^^^^^
  File "C:\Users\A\Desktop\Digitall Skills\RH_App\venv\Lib\site-packages\django\db\models\manager.py", line 87, in manager_method
    return getattr(self.get_queryset(), name)(*args, **kwargs)
           ~~~~~~~~~~~~~~~~~~~~~~~~~~~~~~~~~~^^^^^^^^^^^^^^^^^
  File "C:\Users\A\Desktop\Digitall Skills\RH_App\venv\Lib\site-packages\django\db\models\query.py", line 643, in get
    num = len(clone)
  File "C:\Users\A\Desktop\Digitall Skills\RH_App\venv\Lib\site-packages\django\db\models\query.py", line 380, in __len__
    self._fetch_all()
    ~~~~~~~~~~~~~~~^^
  File "C:\Users\A\Desktop\Digitall Skills\RH_App\venv\Lib\site-packages\django\db\models\query.py", line 1926, in _fetch_all
    self._result_cache = list(self._iterable_class(self))
                         ~~~~^^^^^^^^^^^^^^^^^^^^^^^^^^^^
  File "C:\Users\A\Desktop\Digitall Skills\RH_App\venv\Lib\site-packages\django\db\models\query.py", line 91, in __iter__
    results = compiler.execute_sql(
        chunked_fetch=self.chunked_fetch, chunk_size=self.chunk_size
    )
  File "C:\Users\A\Desktop\Digitall Skills\RH_App\venv\Lib\site-packages\django\db\models\sql\compiler.py", line 1562, in execute_sql
    cursor.execute(sql, params)
    ~~~~~~~~~~~~~~^^^^^^^^^^^^^
  File "C:\Users\A\Desktop\Digitall Skills\RH_App\venv\Lib\site-packages\django\db\backends\utils.py", line 122, in execute
    return super().execute(sql, params)
           ~~~~~~~~~~~~~~~^^^^^^^^^^^^^
  File "C:\Users\A\Desktop\Digitall Skills\RH_App\venv\Lib\site-packages\django\db\backends\utils.py", line 79, in execute
    return self._execute_with_wrappers(
           ~~~~~~~~~~~~~~~~~~~~~~~~~~~^
        sql, params, many=False, executor=self._execute
        ^^^^^^^^^^^^^^^^^^^^^^^^^^^^^^^^^^^^^^^^^^^^^^^
    )
    ^
  File "C:\Users\A\Desktop\Digitall Skills\RH_App\venv\Lib\site-packages\django\db\backends\utils.py", line 92, in _execute_with_wrappers
    return executor(sql, params, many, context)
  File "C:\Users\A\Desktop\Digitall Skills\RH_App\venv\Lib\site-packages\django\db\backends\utils.py", line 100, in _execute
    with self.db.wrap_database_errors:
         ^^^^^^^^^^^^^^^^^^^^^^^^^^^^
  File "C:\Users\A\Desktop\Digitall Skills\RH_App\venv\Lib\site-packages\django\db\utils.py", line 91, in __exit__
    raise dj_exc_value.with_traceback(traceback) from exc_value
  File "C:\Users\A\Desktop\Digitall Skills\RH_App\venv\Lib\site-packages\django\db\backends\utils.py", line 105, in _execute
    return self.cursor.execute(sql, params)
           ~~~~~~~~~~~~~~~~~~~^^^^^^^^^^^^^
  File "C:\Users\A\Desktop\Digitall Skills\RH_App\venv\Lib\site-packages\django\db\backends\sqlite3\base.py", line 328, in execute
    return super().execute(query, params)
           ~~~~~~~~~~~~~~~^^^^^^^^^^^^^^^
django.db.utils.OperationalError: no such table: users
ERROR 2025-08-23 23:22:57,300 basehttp 13140 19520 "POST /api/auth/login/ HTTP/1.1" 500 229572
ERROR 2025-09-01 21:33:35,657 log 22380 17948 Internal Server Error: /api/auth/login/
Traceback (most recent call last):
  File "C:\Users\A\Desktop\Digitall Skills\RH_App\venv\Lib\site-packages\django\core\handlers\exception.py", line 55, in inner
    response = get_response(request)
  File "C:\Users\A\Desktop\Digitall Skills\RH_App\venv\Lib\site-packages\django\core\handlers\base.py", line 197, in _get_response
    response = wrapped_callback(request, *callback_args, **callback_kwargs)
  File "C:\Users\A\Desktop\Digitall Skills\RH_App\venv\Lib\site-packages\django\views\decorators\csrf.py", line 65, in _view_wrapper
    return view_func(request, *args, **kwargs)
  File "C:\Users\A\Desktop\Digitall Skills\RH_App\venv\Lib\site-packages\django\views\generic\base.py", line 104, in view
    return self.dispatch(request, *args, **kwargs)
           ~~~~~~~~~~~~~^^^^^^^^^^^^^^^^^^^^^^^^^^
  File "C:\Users\A\Desktop\Digitall Skills\RH_App\venv\Lib\site-packages\rest_framework\views.py", line 509, in dispatch
    response = self.handle_exception(exc)
  File "C:\Users\A\Desktop\Digitall Skills\RH_App\venv\Lib\site-packages\rest_framework\views.py", line 469, in handle_exception
    self.raise_uncaught_exception(exc)
    ~~~~~~~~~~~~~~~~~~~~~~~~~~~~~^^^^^
  File "C:\Users\A\Desktop\Digitall Skills\RH_App\venv\Lib\site-packages\rest_framework\views.py", line 480, in raise_uncaught_exception
    raise exc
  File "C:\Users\A\Desktop\Digitall Skills\RH_App\venv\Lib\site-packages\rest_framework\views.py", line 506, in dispatch
    response = handler(request, *args, **kwargs)
  File "C:\Users\A\Desktop\Digitall Skills\RH_App\venv\Lib\site-packages\rest_framework\decorators.py", line 50, in handler
    return func(*args, **kwargs)
  File "C:\Users\A\Desktop\Digitall Skills\RH_App\accounts\api_views.py", line 40, in login_view
    'name': user.full_name,
            ^^^^^^^^^^^^^^
AttributeError: 'User' object has no attribute 'full_name'. Did you mean: 'get_full_name'?
ERROR 2025-09-01 21:33:35,683 basehttp 22380 17948 "POST /api/auth/login/ HTTP/1.1" 500 108133
ERROR 2025-09-01 21:34:04,975 log 22380 23352 Internal Server Error: /api/auth/login/
Traceback (most recent call last):
  File "C:\Users\A\Desktop\Digitall Skills\RH_App\venv\Lib\site-packages\django\core\handlers\exception.py", line 55, in inner
    response = get_response(request)
  File "C:\Users\A\Desktop\Digitall Skills\RH_App\venv\Lib\site-packages\django\core\handlers\base.py", line 197, in _get_response
    response = wrapped_callback(request, *callback_args, **callback_kwargs)
  File "C:\Users\A\Desktop\Digitall Skills\RH_App\venv\Lib\site-packages\django\views\decorators\csrf.py", line 65, in _view_wrapper
    return view_func(request, *args, **kwargs)
  File "C:\Users\A\Desktop\Digitall Skills\RH_App\venv\Lib\site-packages\django\views\generic\base.py", line 104, in view
    return self.dispatch(request, *args, **kwargs)
           ~~~~~~~~~~~~~^^^^^^^^^^^^^^^^^^^^^^^^^^
  File "C:\Users\A\Desktop\Digitall Skills\RH_App\venv\Lib\site-packages\rest_framework\views.py", line 509, in dispatch
    response = self.handle_exception(exc)
  File "C:\Users\A\Desktop\Digitall Skills\RH_App\venv\Lib\site-packages\rest_framework\views.py", line 469, in handle_exception
    self.raise_uncaught_exception(exc)
    ~~~~~~~~~~~~~~~~~~~~~~~~~~~~~^^^^^
  File "C:\Users\A\Desktop\Digitall Skills\RH_App\venv\Lib\site-packages\rest_framework\views.py", line 480, in raise_uncaught_exception
    raise exc
  File "C:\Users\A\Desktop\Digitall Skills\RH_App\venv\Lib\site-packages\rest_framework\views.py", line 506, in dispatch
    response = handler(request, *args, **kwargs)
  File "C:\Users\A\Desktop\Digitall Skills\RH_App\venv\Lib\site-packages\rest_framework\decorators.py", line 50, in handler
    return func(*args, **kwargs)
  File "C:\Users\A\Desktop\Digitall Skills\RH_App\accounts\api_views.py", line 40, in login_view
    'name': user.full_name,
            ^^^^^^^^^^^^^^
AttributeError: 'User' object has no attribute 'full_name'. Did you mean: 'get_full_name'?
ERROR 2025-09-01 21:34:04,984 basehttp 22380 23352 "POST /api/auth/login/ HTTP/1.1" 500 108133
ERROR 2025-09-01 21:37:22,268 log 22380 26996 Internal Server Error: /api/auth/login/
Traceback (most recent call last):
  File "C:\Users\A\Desktop\Digitall Skills\RH_App\venv\Lib\site-packages\django\core\handlers\exception.py", line 55, in inner
    response = get_response(request)
  File "C:\Users\A\Desktop\Digitall Skills\RH_App\venv\Lib\site-packages\django\core\handlers\base.py", line 197, in _get_response
    response = wrapped_callback(request, *callback_args, **callback_kwargs)
  File "C:\Users\A\Desktop\Digitall Skills\RH_App\venv\Lib\site-packages\django\views\decorators\csrf.py", line 65, in _view_wrapper
    return view_func(request, *args, **kwargs)
  File "C:\Users\A\Desktop\Digitall Skills\RH_App\venv\Lib\site-packages\django\views\generic\base.py", line 104, in view
    return self.dispatch(request, *args, **kwargs)
           ~~~~~~~~~~~~~^^^^^^^^^^^^^^^^^^^^^^^^^^
  File "C:\Users\A\Desktop\Digitall Skills\RH_App\venv\Lib\site-packages\rest_framework\views.py", line 509, in dispatch
    response = self.handle_exception(exc)
  File "C:\Users\A\Desktop\Digitall Skills\RH_App\venv\Lib\site-packages\rest_framework\views.py", line 469, in handle_exception
    self.raise_uncaught_exception(exc)
    ~~~~~~~~~~~~~~~~~~~~~~~~~~~~~^^^^^
  File "C:\Users\A\Desktop\Digitall Skills\RH_App\venv\Lib\site-packages\rest_framework\views.py", line 480, in raise_uncaught_exception
    raise exc
  File "C:\Users\A\Desktop\Digitall Skills\RH_App\venv\Lib\site-packages\rest_framework\views.py", line 506, in dispatch
    response = handler(request, *args, **kwargs)
  File "C:\Users\A\Desktop\Digitall Skills\RH_App\venv\Lib\site-packages\rest_framework\decorators.py", line 50, in handler
    return func(*args, **kwargs)
  File "C:\Users\A\Desktop\Digitall Skills\RH_App\accounts\api_views.py", line 40, in login_view
    'name': user.full_name,
            ^^^^^^^^^^^^^^
AttributeError: 'User' object has no attribute 'full_name'. Did you mean: 'get_full_name'?
ERROR 2025-09-01 21:37:22,295 basehttp 22380 26996 "POST /api/auth/login/ HTTP/1.1" 500 108133
ERROR 2025-09-01 21:53:36,953 log 21792 5008 Internal Server Error: /api/auth/login/
Traceback (most recent call last):
  File "C:\Users\A\Desktop\Digitall Skills\RH_App\venv\Lib\site-packages\django\core\handlers\exception.py", line 55, in inner
    response = get_response(request)
  File "C:\Users\A\Desktop\Digitall Skills\RH_App\venv\Lib\site-packages\django\core\handlers\base.py", line 197, in _get_response
    response = wrapped_callback(request, *callback_args, **callback_kwargs)
  File "C:\Users\A\Desktop\Digitall Skills\RH_App\venv\Lib\site-packages\django\views\decorators\csrf.py", line 65, in _view_wrapper
    return view_func(request, *args, **kwargs)
  File "C:\Users\A\Desktop\Digitall Skills\RH_App\venv\Lib\site-packages\django\views\generic\base.py", line 104, in view
    return self.dispatch(request, *args, **kwargs)
           ~~~~~~~~~~~~~^^^^^^^^^^^^^^^^^^^^^^^^^^
  File "C:\Users\A\Desktop\Digitall Skills\RH_App\venv\Lib\site-packages\rest_framework\views.py", line 509, in dispatch
    response = self.handle_exception(exc)
  File "C:\Users\A\Desktop\Digitall Skills\RH_App\venv\Lib\site-packages\rest_framework\views.py", line 469, in handle_exception
    self.raise_uncaught_exception(exc)
    ~~~~~~~~~~~~~~~~~~~~~~~~~~~~~^^^^^
  File "C:\Users\A\Desktop\Digitall Skills\RH_App\venv\Lib\site-packages\rest_framework\views.py", line 480, in raise_uncaught_exception
    raise exc
  File "C:\Users\A\Desktop\Digitall Skills\RH_App\venv\Lib\site-packages\rest_framework\views.py", line 506, in dispatch
    response = handler(request, *args, **kwargs)
  File "C:\Users\A\Desktop\Digitall Skills\RH_App\venv\Lib\site-packages\rest_framework\decorators.py", line 50, in handler
    return func(*args, **kwargs)
  File "C:\Users\A\Desktop\Digitall Skills\RH_App\accounts\api_views.py", line 40, in login_view
    'name': user.full_name,
            ^^^^^^^^^^^^^^
AttributeError: 'User' object has no attribute 'full_name'. Did you mean: 'get_full_name'?
ERROR 2025-09-01 21:53:36,970 basehttp 21792 5008 "POST /api/auth/login/ HTTP/1.1" 500 108178
ERROR 2025-09-01 21:54:29,694 log 21792 16652 Internal Server Error: /api/auth/login/
Traceback (most recent call last):
  File "C:\Users\A\Desktop\Digitall Skills\RH_App\venv\Lib\site-packages\django\core\handlers\exception.py", line 55, in inner
    response = get_response(request)
  File "C:\Users\A\Desktop\Digitall Skills\RH_App\venv\Lib\site-packages\django\core\handlers\base.py", line 197, in _get_response
    response = wrapped_callback(request, *callback_args, **callback_kwargs)
  File "C:\Users\A\Desktop\Digitall Skills\RH_App\venv\Lib\site-packages\django\views\decorators\csrf.py", line 65, in _view_wrapper
    return view_func(request, *args, **kwargs)
  File "C:\Users\A\Desktop\Digitall Skills\RH_App\venv\Lib\site-packages\django\views\generic\base.py", line 104, in view
    return self.dispatch(request, *args, **kwargs)
           ~~~~~~~~~~~~~^^^^^^^^^^^^^^^^^^^^^^^^^^
  File "C:\Users\A\Desktop\Digitall Skills\RH_App\venv\Lib\site-packages\rest_framework\views.py", line 509, in dispatch
    response = self.handle_exception(exc)
  File "C:\Users\A\Desktop\Digitall Skills\RH_App\venv\Lib\site-packages\rest_framework\views.py", line 469, in handle_exception
    self.raise_uncaught_exception(exc)
    ~~~~~~~~~~~~~~~~~~~~~~~~~~~~~^^^^^
  File "C:\Users\A\Desktop\Digitall Skills\RH_App\venv\Lib\site-packages\rest_framework\views.py", line 480, in raise_uncaught_exception
    raise exc
  File "C:\Users\A\Desktop\Digitall Skills\RH_App\venv\Lib\site-packages\rest_framework\views.py", line 506, in dispatch
    response = handler(request, *args, **kwargs)
  File "C:\Users\A\Desktop\Digitall Skills\RH_App\venv\Lib\site-packages\rest_framework\decorators.py", line 50, in handler
    return func(*args, **kwargs)
  File "C:\Users\A\Desktop\Digitall Skills\RH_App\accounts\api_views.py", line 40, in login_view
    'name': user.full_name,
            ^^^^^^^^^^^^^^
AttributeError: 'User' object has no attribute 'full_name'. Did you mean: 'get_full_name'?
ERROR 2025-09-01 21:54:29,715 basehttp 21792 16652 "POST /api/auth/login/ HTTP/1.1" 500 108178
ERROR 2025-09-01 22:03:56,575 log 11344 3592 Internal Server Error: /api/auth/login/
Traceback (most recent call last):
  File "C:\Users\A\Desktop\Digitall Skills\RH_App\venv\Lib\site-packages\django\core\handlers\exception.py", line 55, in inner
    response = get_response(request)
  File "C:\Users\A\Desktop\Digitall Skills\RH_App\venv\Lib\site-packages\django\core\handlers\base.py", line 197, in _get_response
    response = wrapped_callback(request, *callback_args, **callback_kwargs)
  File "C:\Users\A\Desktop\Digitall Skills\RH_App\venv\Lib\site-packages\django\views\decorators\csrf.py", line 65, in _view_wrapper
    return view_func(request, *args, **kwargs)
  File "C:\Users\A\Desktop\Digitall Skills\RH_App\venv\Lib\site-packages\django\views\generic\base.py", line 104, in view
    return self.dispatch(request, *args, **kwargs)
           ~~~~~~~~~~~~~^^^^^^^^^^^^^^^^^^^^^^^^^^
  File "C:\Users\A\Desktop\Digitall Skills\RH_App\venv\Lib\site-packages\rest_framework\views.py", line 509, in dispatch
    response = self.handle_exception(exc)
  File "C:\Users\A\Desktop\Digitall Skills\RH_App\venv\Lib\site-packages\rest_framework\views.py", line 469, in handle_exception
    self.raise_uncaught_exception(exc)
    ~~~~~~~~~~~~~~~~~~~~~~~~~~~~~^^^^^
  File "C:\Users\A\Desktop\Digitall Skills\RH_App\venv\Lib\site-packages\rest_framework\views.py", line 480, in raise_uncaught_exception
    raise exc
  File "C:\Users\A\Desktop\Digitall Skills\RH_App\venv\Lib\site-packages\rest_framework\views.py", line 506, in dispatch
    response = handler(request, *args, **kwargs)
  File "C:\Users\A\Desktop\Digitall Skills\RH_App\venv\Lib\site-packages\rest_framework\decorators.py", line 50, in handler
    return func(*args, **kwargs)
  File "C:\Users\A\Desktop\Digitall Skills\RH_App\accounts\api_views.py", line 43, in login_view
    'name': user.full_name,
            ^^^^^^^^^^^^^^
AttributeError: 'User' object has no attribute 'full_name'. Did you mean: 'get_full_name'?
ERROR 2025-09-01 22:03:56,622 basehttp 11344 3592 "POST /api/auth/login/ HTTP/1.1" 500 108178
ERROR 2025-09-01 22:09:04,513 log 11344 27344 Internal Server Error: /api/auth/login/
Traceback (most recent call last):
  File "C:\Users\A\Desktop\Digitall Skills\RH_App\venv\Lib\site-packages\django\core\handlers\exception.py", line 55, in inner
    response = get_response(request)
  File "C:\Users\A\Desktop\Digitall Skills\RH_App\venv\Lib\site-packages\django\core\handlers\base.py", line 197, in _get_response
    response = wrapped_callback(request, *callback_args, **callback_kwargs)
  File "C:\Users\A\Desktop\Digitall Skills\RH_App\venv\Lib\site-packages\django\views\decorators\csrf.py", line 65, in _view_wrapper
    return view_func(request, *args, **kwargs)
  File "C:\Users\A\Desktop\Digitall Skills\RH_App\venv\Lib\site-packages\django\views\generic\base.py", line 104, in view
    return self.dispatch(request, *args, **kwargs)
           ~~~~~~~~~~~~~^^^^^^^^^^^^^^^^^^^^^^^^^^
  File "C:\Users\A\Desktop\Digitall Skills\RH_App\venv\Lib\site-packages\rest_framework\views.py", line 509, in dispatch
    response = self.handle_exception(exc)
  File "C:\Users\A\Desktop\Digitall Skills\RH_App\venv\Lib\site-packages\rest_framework\views.py", line 469, in handle_exception
    self.raise_uncaught_exception(exc)
    ~~~~~~~~~~~~~~~~~~~~~~~~~~~~~^^^^^
  File "C:\Users\A\Desktop\Digitall Skills\RH_App\venv\Lib\site-packages\rest_framework\views.py", line 480, in raise_uncaught_exception
    raise exc
  File "C:\Users\A\Desktop\Digitall Skills\RH_App\venv\Lib\site-packages\rest_framework\views.py", line 506, in dispatch
    response = handler(request, *args, **kwargs)
  File "C:\Users\A\Desktop\Digitall Skills\RH_App\venv\Lib\site-packages\rest_framework\decorators.py", line 50, in handler
    return func(*args, **kwargs)
  File "C:\Users\A\Desktop\Digitall Skills\RH_App\accounts\api_views.py", line 43, in login_view
    'name': user.full_name,
            ^^^^^^^^^^^^^^
AttributeError: 'User' object has no attribute 'full_name'. Did you mean: 'get_full_name'?
ERROR 2025-09-01 22:09:04,534 basehttp 11344 27344 "POST /api/auth/login/ HTTP/1.1" 500 108178
ERROR 2025-09-01 22:19:52,484 log 11344 19540 Internal Server Error: /api/auth/login/
Traceback (most recent call last):
  File "C:\Users\A\Desktop\Digitall Skills\RH_App\venv\Lib\site-packages\django\core\handlers\exception.py", line 55, in inner
    response = get_response(request)
  File "C:\Users\A\Desktop\Digitall Skills\RH_App\venv\Lib\site-packages\django\core\handlers\base.py", line 197, in _get_response
    response = wrapped_callback(request, *callback_args, **callback_kwargs)
  File "C:\Users\A\Desktop\Digitall Skills\RH_App\venv\Lib\site-packages\django\views\decorators\csrf.py", line 65, in _view_wrapper
    return view_func(request, *args, **kwargs)
  File "C:\Users\A\Desktop\Digitall Skills\RH_App\venv\Lib\site-packages\django\views\generic\base.py", line 104, in view
    return self.dispatch(request, *args, **kwargs)
           ~~~~~~~~~~~~~^^^^^^^^^^^^^^^^^^^^^^^^^^
  File "C:\Users\A\Desktop\Digitall Skills\RH_App\venv\Lib\site-packages\rest_framework\views.py", line 509, in dispatch
    response = self.handle_exception(exc)
  File "C:\Users\A\Desktop\Digitall Skills\RH_App\venv\Lib\site-packages\rest_framework\views.py", line 469, in handle_exception
    self.raise_uncaught_exception(exc)
    ~~~~~~~~~~~~~~~~~~~~~~~~~~~~~^^^^^
  File "C:\Users\A\Desktop\Digitall Skills\RH_App\venv\Lib\site-packages\rest_framework\views.py", line 480, in raise_uncaught_exception
    raise exc
  File "C:\Users\A\Desktop\Digitall Skills\RH_App\venv\Lib\site-packages\rest_framework\views.py", line 506, in dispatch
    response = handler(request, *args, **kwargs)
  File "C:\Users\A\Desktop\Digitall Skills\RH_App\venv\Lib\site-packages\rest_framework\decorators.py", line 50, in handler
    return func(*args, **kwargs)
  File "C:\Users\A\Desktop\Digitall Skills\RH_App\accounts\api_views.py", line 43, in login_view
    'name': user.full_name,
            ^^^^^^^^^^^^^^
AttributeError: 'User' object has no attribute 'full_name'. Did you mean: 'get_full_name'?
ERROR 2025-09-01 22:19:52,543 basehttp 11344 19540 "POST /api/auth/login/ HTTP/1.1" 500 108189
